Workbook

Sheet 요약
C1: TODAY | D1: DOT | K1: * 설 연휴 | M1: * 3.1절 대체 휴일 | U1: * 근로자의 날 | V1: * 어린이날 | Y1: * 대체공휴일 | Z1: * 선거 | AH1: * DP 하계 휴무 | AI1: * DP 하계 휴무 | AK1: * 대체공휴일 | AP1: * 추석 연휴 | AR1: * 대체공휴일 | BC1: * 성탄절
C2: =TODAY() -> 46174 | D2: =WEEKNUM(C2)-1 -> 22 | AR2: * 한글날
B3: 1. 시험/양시 계획 반영 현황 (ECN) | E3: 01/05~01/10 | K3: Working Day 1 | M3: Working Day 4 | U3: Working Day 4 | V3: Working Day 4 | Y3: Working Day 4 | Z3: Working Day 4 | AH3: Working Day 4 | AI3: Working Day 1 | AK3: Working Day 4 | AP3: Working Day 3 | AR3: Working Day 3 | BC3: Working Day 4
B4: DOT | D4: SUM | E4: 1 | F4: 2 | G4: 3 | H4: 4 | I4: 5 | J4: 6 | K4: 7 | L4: 8 | M4: 9 | N4: 10 | O4: 11 | P4: 12 | Q4: 13 | R4: 14 | S4: 15 | T4: 16 | U4: 17 | V4: 18 | W4: 19 | X4: 20 | Y4: 21 | Z4: 22 | AA4: 23 | AB4: 24 | AC4: 25 | AD4: 26 | AE4: 27 | AF4: 28 | AG4: 29 | AH4: 30 | AI4: 31 | AJ4: 32 | AK4: 33 | AL4: 34 | AM4: 35 | AN4: 36 | AO4: 37 | AP4: 38 | AQ4: 39 | AR4: 40 | AS4: 41 | AT4: 42 | AU4: 43 | AV4: 44 | AW4: 45 | AX4: 46 | AY4: 47 | AZ4: 48 | BA4: 49 | BB4: 50 | BC4: 51 | BD4: 52
B5: 시험용 | C5: TEPS 요청 | D5: =SUM(E5:BD5) -> 397 | E5: =시험요청!C2 -> 17 | F5: =시험요청!D2 -> 16 | G5: =시험요청!E2 -> 7 | H5: =시험요청!F2 -> 14 | I5: =시험요청!G2 -> 17 | J5: =시험요청!H2 -> 11 | K5: =시험요청!I2 -> 6 | L5: =시험요청!J2 -> 18 | ... BD5: =시험요청!BB2 -> 0
C6: 기타 요청 | D6: =SUM(E6:BD6) -> 19 | E6: =시험요청!C6 -> 0 | F6: =시험요청!D6 -> 0 | G6: =시험요청!E6 -> 0 | H6: =시험요청!F6 -> 0 | I6: =시험요청!G6 -> 0 | J6: =시험요청!H6 -> 0 | K6: =시험요청!I6 -> 0 | L6: =시험요청!J6 -> 0 | ... BD6: =시험요청!BB6 -> 0
C7: 반영 (최종) | D7: =SUM(E7:BD7) -> 271 | E7: =시험요청!C3 -> 7 | F7: =시험요청!D3 -> 7 | G7: =시험요청!E3 -> 5 | H7: =시험요청!F3 -> 13 | I7: =시험요청!G3 -> 14 | J7: =시험요청!H3 -> 7 | K7: =시험요청!I3 -> 1 | L7: =시험요청!J3 -> 11 | ... BD7: =시험요청!BB3 -> 0
C8: 최종본 (취소) | D8: =SUM(E8:BD8) -> 12 | E8: =시험용!D$5 -> 0 | F8: =시험용!E$5 -> 0 | G8: =시험용!F$5 -> 0 | H8: =시험용!G$5 -> 0 | I8: =시험용!H$5 -> 0 | J8: =시험용!I$5 -> 0 | K8: =시험용!J$5 -> 0 | L8: =시험용!K$5 -> 1 | ... BD8: =시험용!BC$5 -> 0
B9: 양시 | C9: TEPS 요청 | D9: =SUM(E9:BD9) -> 215 | E9: =양시요청!C2 -> 12 | F9: =양시요청!D2 -> 1 | G9: =양시요청!E2 -> 10 | H9: =양시요청!F2 -> 14 | I9: =양시요청!G2 -> 13 | J9: =양시요청!H2 -> 13 | K9: =양시요청!I2 -> 9 | L9: =양시요청!J2 -> 17 | ... BD9: =양시요청!BB2 -> 0
C10: 반영 (최종) | D10: =SUM(E10:BD10) -> 131 | E10: =양시요청!C3 -> 12 | F10: =양시요청!D3 -> 0 | G10: =양시요청!E3 -> 7 | H10: =양시요청!F3 -> 7 | I10: =양시요청!G3 -> 9 | J10: =양시요청!H3 -> 8 | K10: =양시요청!I3 -> 3 | L10: =양시요청!J3 -> 9 | ... BD10: =양시요청!BB3 -> 0
C11: 최종본 (취소) | D11: =SUM(E11:BD11) -> 12 | E11: =양시!C4 -> 1 | F11: =양시!D4 -> 0 | G11: =양시!E4 -> 0 | H11: =양시!F4 -> 1 | I11: =양시!G4 -> 1 | J11: =양시!H4 -> 1 | K11: =양시!I4 -> 0 | L11: =양시!J4 -> 1 | ... BD11: =양시!BB4 -> 0
B12: TBR (시험/양시) | C12: TEPS 요청 | D12: =SUM(E12:BD12) -> 0 | E12: =TBR!D2 -> 0 | F12: =TBR!E2 -> 0 | G12: =TBR!F2 -> 0 | H12: =TBR!G2 -> 0 | I12: =TBR!H2 -> 0 | J12: =TBR!I2 -> 0 | K12: =TBR!J2 -> 0 | L12: =TBR!K2 -> 0 | ... BD12: =TBR!BC2 -> 0
C13: 반영 (최종) | D13: =SUM(E13:BD13) -> 0 | E13: =E12 -> 0 | F13: =F12 -> 0 | G13: =G12 -> 0 | H13: =H12 -> 0 | I13: =I12 -> 0 | J13: =J12 -> 0 | K13: =K12 -> 0 | L13: =L12 -> 0 | ... BD13: =BD12 -> 0
C14: 최종본 (취소) | D14: =SUM(E14:BD14) -> 0 | E14: =TBR!D6 -> 0 | F14: =TBR!E6 -> 0 | G14: =TBR!F6 -> 0 | H14: =TBR!G6 -> 0 | I14: =TBR!H6 -> 0 | J14: =TBR!I6 -> 0 | K14: =TBR!J6 -> 0 | L14: =TBR!K6 -> 0 | ... BD14: =TBR!BC6 -> 0
B15: Sub Total (반영, 취소 포함) | D15: =SUM(E15:BD15) -> 402 | E15: =SUM(E7,E10,E12) -> 19 | F15: =SUM(F7,F10,F12) -> 7 | G15: =SUM(G7,G10,G12) -> 12 | H15: =SUM(H7,H10,H12) -> 20 | I15: =SUM(I7,I10,I12) -> 23 | J15: =SUM(J7,J10,J12) -> 15 | K15: =SUM(K7,K10,K12) -> 4 | L15: =SUM(L7,L10,L12) -> 20 | ... BD15: =SUM(BD7,BD10,BD12) -> 0
C16: 계획준수율 | D16: =(D15-D11-D8)/D15 -> 0.94029851 | E16: =(E15-E11-E8)/E15 -> 0.94736842 | F16: =(F15-F11-F8)/F15 -> 1 | G16: =(G15-G11-G8)/G15 -> 1 | H16: =(H15-H11-H8)/H15 -> 0.95 | I16: =(I15-I11-I8)/I15 -> 0.95652174 | J16: =(J15-J11-J8)/J15 -> 0.93333333 | K16: =(K15-K11-K8)/K15 -> 1 | ... BD16: =(BD15-BD11-BD8)/BD15 -> #DIV/0!
C17: 요청 (Total) | E17: =E5+E12 -> 17 | F17: =F5+F12 -> 16 | G17: =G5+G12 -> 7 | H17: =H5+H12 -> 14 | I17: =I5+I12 -> 17 | J17: =J5+J12 -> 11 | K17: =K5+K12 -> 6 | L17: =L5+L12 -> 18 | ... BD17: =BD5+BD12 -> 0
C18: 반영 (Total) | E18: =E7+E13 -> 7 | F18: =F7+F13 -> 7 | G18: =G7+G13 -> 5 | H18: =H7+H13 -> 13 | I18: =I7+I13 -> 14 | J18: =J7+J13 -> 7 | K18: =K7+K13 -> 1 | L18: =L7+L13 -> 11 | ... BD18: =BD7+BD13 -> 0
B19: 2. 시험/양시 제조 수량 | E19: =E5+E9+E12 -> 29 | F19: =F5+F9+F12 -> 17 | G19: =G5+G9+G12 -> 17 | H19: =H5+H9+H12 -> 28 | I19: =I5+I9+I12 -> 30 | J19: =J5+J9+J12 -> 24 | K19: =K5+K9+K12 -> 15 | L19: =L5+L9+L12 -> 35 | ... BD19: =BD5+BD9+BD12 -> 0
B20: -. Spec. EA (Racing 포함)
B21: DOT | D21: SUM | E21: 1 | F21: 2 | G21: 3 | H21: 4 | I21: 5 | J21: 6 | K21: 7 | L21: 8 | M21: 9 | N21: 10 | O21: 11 | P21: 12 | Q21: 13 | R21: 14 | S21: 15 | T21: 16 | U21: 17 | V21: 18 | W21: 19 | X21: 20 | Y21: 21 | Z21: 22 | AA21: 23 | AB21: 24 | AC21: 25 | AD21: 26 | AE21: 27 | AF21: 28 | AG21: 29 | AH21: 30 | AI21: 31 | AJ21: 32 | AK21: 33 | AL21: 34 | AM21: 35 | AN21: 36 | AO21: 37 | AP21: 38 | AQ21: 39 | AR21: 40 | AS21: 41 | AT21: 42 | AU21: 43 | AV21: 44 | AW21: 45 | AX21: 46 | AY21: 47 | AZ21: 48 | BA21: 49 | BB21: 50 | BC21: 51 | BD21: 52
B22: 시험용 Spec. EA | D22: =SUM(E22:BD22) -> 420 | E22: =시험용!D7 -> 7 | F22: =시험용!E7 -> 7 | G22: =시험용!F7 -> 5 | H22: =시험용!G7 -> 15 | I22: =시험용!H7 -> 23 | J22: =시험용!I7 -> 15 | K22: =시험용!J7 -> 1 | L22: =시험용!K7 -> 19 | ... S22: =시험용!R7 -> 13 | T22: 36 | U22: =시험용!T7 -> 21 | V22: =시험용!U7 -> 32 | W22: =시험용!V7 -> 25 | X22: =시험용!W7 -> 27 | Y22: =시험용!X7 -> 9 | Z22: =시험용!Y7 -> 21 | AA22: =시험용!Z7 -> 15 | AB22: =시험용!AA7 -> 0 | ... BD22: =시험용!BC7 -> 0
B23: 양시 Spec. EA | D23: =SUM(E23:BD23) -> 131 | E23: =양시!C6 -> 12 | F23: =양시!D6 -> 0 | G23: =양시!E6 -> 7 | H23: =양시!F6 -> 7 | I23: =양시!G6 -> 9 | J23: =양시!H6 -> 8 | K23: =양시!I6 -> 3 | L23: =양시!J6 -> 9 | ... BD23: =양시!BB6 -> 0
B24: TBR Spec. EA | D24: =SUM(E24:BD24) -> 0 | E24: =TBR!D8 -> 0 | F24: =TBR!E8 -> 0 | G24: =TBR!F8 -> 0 | H24: =TBR!G8 -> 0 | I24: =TBR!H8 -> 0 | J24: =TBR!I8 -> 0 | K24: =TBR!J8 -> 0 | L24: =TBR!K8 -> 0 | ... BD24: =TBR!BC8 -> 0
B25: Sub Total | D25: =SUM(E25:BD25) -> 551 | E25: =SUM(E22:E24) -> 19 | F25: =SUM(F22:F24) -> 7 | G25: =SUM(G22:G24) -> 12 | H25: =SUM(H22:H24) -> 22 | I25: =SUM(I22:I24) -> 32 | J25: =SUM(J22:J24) -> 23 | K25: =SUM(K22:K24) -> 4 | L25: =SUM(L22:L24) -> 28 | ... BD25: =SUM(BD22:BD24) -> 0
B27: -. Tire 제조 EA (Racing 포함)
B28: DOT | D28: SUM | E28: 1 | F28: 2 | G28: 3 | H28: 4 | I28: 5 | J28: 6 | K28: 7 | L28: 8 | M28: 9 | N28: 10 | O28: 11 | P28: 12 | Q28: 13 | R28: 14 | S28: 15 | T28: 16 | U28: 17 | V28: 18 | W28: 19 | X28: 20 | Y28: 21 | Z28: 22 | AA28: 23 | AB28: 24 | AC28: 25 | AD28: 26 | AE28: 27 | AF28: 28 | AG28: 29 | AH28: 30 | AI28: 31 | AJ28: 32 | AK28: 33 | AL28: 34 | AM28: 35 | AN28: 36 | AO28: 37 | AP28: 38 | AQ28: 39 | AR28: 40 | AS28: 41 | AT28: 42 | AU28: 43 | AV28: 44 | AW28: 45 | AX28: 46 | AY28: 47 | AZ28: 48 | BA28: 49 | BB28: 50 | BC28: 51 | BD28: 52
B29: 시험용 Tire EA (계획) | D29: =SUM(E29:BD29) -> 7055 | E29: =시험용!D8 -> 86 | F29: =시험용!E8 -> 102 | G29: =시험용!F8 -> 58 | H29: =시험용!G8 -> 298 | I29: =시험용!H8 -> 306 | J29: =시험용!I8 -> 204 | K29: =시험용!J8 -> 14 | L29: =시험용!K8 -> 288 | ... BD29: =시험용!BC8 -> 0
B30: 양시 Tire EA (실적) | D30: =SUM(E30:BD30) -> 14164 | E30: =양시!C7 -> 1222 | F30: =양시!D7 -> 0 | G30: =양시!E7 -> 828 | H30: =양시!F7 -> 862 | I30: =양시!G7 -> 793 | J30: =양시!H7 -> 822 | K30: =양시!I7 -> 225 | L30: =양시!J7 -> 1079 | ... BD30: =양시!BB7 -> 0
B31: TBR Tire EA (계획) | D31: =SUM(E31:BD31) -> 0 | E31: =TBR!D9 -> 0 | F31: =TBR!E9 -> 0 | G31: =TBR!F9 -> 0 | H31: =TBR!G9 -> 0 | I31: =TBR!H9 -> 0 | J31: =TBR!I9 -> 0 | K31: =TBR!J9 -> 0 | L31: =TBR!K9 -> 0 | ... BD31: =TBR!BC9 -> 0
B32: Sub Total | D32: =SUM(E32:BD32) -> 21219 | E32: =SUM(E29:E31) -> 1308 | F32: =SUM(F29:F31) -> 102 | G32: =SUM(G29:G31) -> 886 | H32: =SUM(H29:H31) -> 1160 | I32: =SUM(I29:I31) -> 1099 | J32: =SUM(J29:J31) -> 1026 | K32: =SUM(K29:K31) -> 239 | L32: =SUM(L29:L31) -> 1367 | ... BD32: =SUM(BD29:BD31) -> 0
B34: -. 시험용 Racing 제조
B35: DOT | D35: SUM | E35: 1 | F35: 2 | G35: 3 | H35: 4 | I35: 5 | J35: 6 | K35: 7 | L35: 8 | M35: 9 | N35: 10 | O35: 11 | P35: 12 | Q35: 13 | R35: 14 | S35: 15 | T35: 16 | U35: 17 | V35: 18 | W35: 19 | X35: 20 | Y35: 21 | Z35: 22 | AA35: 23 | AB35: 24 | AC35: 25 | AD35: 26 | AE35: 27 | AF35: 28 | AG35: 29 | AH35: 30 | AI35: 31 | AJ35: 32 | AK35: 33 | AL35: 34 | AM35: 35 | AN35: 36 | AO35: 37 | AP35: 38 | AQ35: 39 | AR35: 40 | AS35: 41 | AT35: 42 | AU35: 43 | AV35: 44 | AW35: 45 | AX35: 46 | AY35: 47 | AZ35: 48 | BA35: 49 | BB35: 50 | BC35: 51 | BD35: 52
B36: ECN EA | D36: =SUM(E36:BD36) -> 51 | F36: 2 | I36: 4 | O36: 10 | P36: 3 | Q36: 7 | T36: 6 | U36: 4 | V36: 6 | W36: 2 | Z36: 7
B37: Spec. EA | D37: =SUM(E37:BD37) -> 93 | F37: 2 | I37: 9 | O37: 22 | P37: 11 | Q37: 7 | T37: 16 | U37: 6 | V37: 7 | W37: 2 | Z37: 11
B38: 시험용 Tire EA (계획) | D38: =SUM(E38:BD38) -> 1296 | F38: 44 | I38: 100 | O38: 208 | P38: 72 | Q38: 140 | T38: 132 | U38: 190 | V38: 258 | W38: 20 | Z38: =11*12 -> 132
B40: -. 양시 Racing 제조
B41: DOT | D41: SUM | E41: 1 | F41: 2 | G41: 3 | H41: 4 | I41: 5 | J41: 6 | K41: 7 | L41: 8 | M41: 9 | N41: 10 | O41: 11 | P41: 12 | Q41: 13 | R41: 14 | S41: 15 | T41: 16 | U41: 17 | V41: 18 | W41: 19 | X41: 20 | Y41: 21 | Z41: 22 | AA41: 23 | AB41: 24 | AC41: 25 | AD41: 26 | AE41: 27 | AF41: 28 | AG41: 29 | AH41: 30 | AI41: 31 | AJ41: 32 | AK41: 33 | AL41: 34 | AM41: 35 | AN41: 36 | AO41: 37 | AP41: 38 | AQ41: 39 | AR41: 40 | AS41: 41 | AT41: 42 | AU41: 43 | AV41: 44 | AW41: 45 | AX41: 46 | AY41: 47 | AZ41: 48 | BA41: 49 | BB41: 50 | BC41: 51 | BD41: 52
B42: ECN EA | D42: =SUM(E42:BD42) -> 17 | E42: 6 | G42: 1 | I42: 2 | P42: 2 | U42: 4 | V42: 2
B43: Spec. EA | D43: =SUM(E43:BD43) -> 17 | E43: 6 | G43: 1 | I43: 2 | P43: 2 | U43: 4 | V43: 2
...

Sheet Graph
AH1: * 설 연휴 | AM1: * 3.1절 대체 휴일 | AU1: * 근로자의 날 | AV1: * 어린이날 대체 휴일 | AZ1: * 선거, 현충일 | BH1: * DP 하계 휴무 | BQ1: * 개천절 | BR1: * 추석 연휴 | CC1: * 성탄절
AC2: ◎ 인치별 시험용 제조 규격 수
AB3: Portion | AC3: DOT | AD3: SUB | AE3: 1 | AF3: 2 | AG3: 3 | AH3: 4 | AI3: 5 | AJ3: 6 | AK3: 7 | AL3: 8 | AM3: 9 | AN3: 10 | AO3: 11 | AP3: 12 | AQ3: 13 | AR3: 14 | AS3: 15 | AT3: 16 | AU3: 17 | AV3: 18 | AW3: 19 | AX3: 20 | AY3: 21 | AZ3: 22 | BA3: 23 | BB3: 24 | BC3: 25 | BD3: 26 | BE3: 27 | BF3: 28 | BG3: 29 | BH3: 30 | BI3: 31 | BJ3: 32 | BK3: 33 | BL3: 34 | BM3: 35 | BN3: 36 | BO3: 37 | BP3: 38 | BQ3: 39 | BR3: 40 | BS3: 41 | BT3: 42 | BU3: 43 | BV3: 44 | BW3: 45 | BX3: 46 | BY3: 47 | BZ3: 48 | CA3: 49 | CB3: 50 | CC3: 51 | CD3: 52
AB4: =AD4/$AD$12 -> 0.011627907 | AC4: 14 | AD4: =SUM(AE4:CD4) -> 3 | AE4: =COUNTIFS(시험용!$B:$B,Graph!AE$3,시험용!$CB:$CB,Graph!$AC4) -> 0 | AF4: =COUNTIFS(시험용!$B:$B,Graph!AF$3,시험용!$CB:$CB,Graph!$AC4) -> 0 | AG4: =COUNTIFS(시험용!$B:$B,Graph!AG$3,시험용!$CB:$CB,Graph!$AC4) -> 0 | AH4: =COUNTIFS(시험용!$B:$B,Graph!AH$3,시험용!$CB:$CB,Graph!$AC4) -> 1 | AI4: =COUNTIFS(시험용!$B:$B,Graph!AI$3,시험용!$CB:$CB,Graph!$AC4) -> 0 | AJ4: =COUNTIFS(시험용!$B:$B,Graph!AJ$3,시험용!$CB:$CB,Graph!$AC4) -> 0 | AK4: =COUNTIFS(시험용!$B:$B,Graph!AK$3,시험용!$CB:$CB,Graph!$AC4) -> 0 | AL4: =COUNTIFS(시험용!$B:$B,Graph!AL$3,시험용!$CB:$CB,Graph!$AC4) -> 0 | ... CD4: =COUNTIFS(시험용!$B:$B,Graph!CD$3,시험용!$CB:$CB,Graph!$AC4) -> 0
AB5: =AD5/$AD$12 -> 0.062015504 | AC5: 15 | AD5: =SUM(AE5:CD5) -> 16 | AE5: =COUNTIFS(시험용!$B:$B,Graph!AE$3,시험용!$CB:$CB,Graph!$AC5) -> 1 | AF5: =COUNTIFS(시험용!$B:$B,Graph!AF$3,시험용!$CB:$CB,Graph!$AC5) -> 0 | AG5: =COUNTIFS(시험용!$B:$B,Graph!AG$3,시험용!$CB:$CB,Graph!$AC5) -> 0 | AH5: =COUNTIFS(시험용!$B:$B,Graph!AH$3,시험용!$CB:$CB,Graph!$AC5) -> 1 | AI5: =COUNTIFS(시험용!$B:$B,Graph!AI$3,시험용!$CB:$CB,Graph!$AC5) -> 1 | AJ5: =COUNTIFS(시험용!$B:$B,Graph!AJ$3,시험용!$CB:$CB,Graph!$AC5) -> 0 | AK5: =COUNTIFS(시험용!$B:$B,Graph!AK$3,시험용!$CB:$CB,Graph!$AC5) -> 0 | AL5: =COUNTIFS(시험용!$B:$B,Graph!AL$3,시험용!$CB:$CB,Graph!$AC5) -> 1 | ... CD5: =COUNTIFS(시험용!$B:$B,Graph!CD$3,시험용!$CB:$CB,Graph!$AC5) -> 0
AB6: =AD6/$AD$12 -> 0.13178295 | AC6: 16 | AD6: =SUM(AE6:CD6) -> 34 | AE6: =COUNTIFS(시험용!$B:$B,Graph!AE$3,시험용!$CB:$CB,Graph!$AC6) -> 0 | AF6: =COUNTIFS(시험용!$B:$B,Graph!AF$3,시험용!$CB:$CB,Graph!$AC6) -> 0 | AG6: =COUNTIFS(시험용!$B:$B,Graph!AG$3,시험용!$CB:$CB,Graph!$AC6) -> 2 | AH6: =COUNTIFS(시험용!$B:$B,Graph!AH$3,시험용!$CB:$CB,Graph!$AC6) -> 4 | AI6: =COUNTIFS(시험용!$B:$B,Graph!AI$3,시험용!$CB:$CB,Graph!$AC6) -> 1 | AJ6: =COUNTIFS(시험용!$B:$B,Graph!AJ$3,시험용!$CB:$CB,Graph!$AC6) -> 1 | AK6: =COUNTIFS(시험용!$B:$B,Graph!AK$3,시험용!$CB:$CB,Graph!$AC6) -> 0 | AL6: =COUNTIFS(시험용!$B:$B,Graph!AL$3,시험용!$CB:$CB,Graph!$AC6) -> 3 | ... CD6: =COUNTIFS(시험용!$B:$B,Graph!CD$3,시험용!$CB:$CB,Graph!$AC6) -> 0
AB7: =AD7/$AD$12 -> 0.10077519 | AC7: 17 | AD7: =SUM(AE7:CD7) -> 26 | AE7: =COUNTIFS(시험용!$B:$B,Graph!AE$3,시험용!$CB:$CB,Graph!$AC7) -> 2 | AF7: =COUNTIFS(시험용!$B:$B,Graph!AF$3,시험용!$CB:$CB,Graph!$AC7) -> 0 | AG7: =COUNTIFS(시험용!$B:$B,Graph!AG$3,시험용!$CB:$CB,Graph!$AC7) -> 0 | AH7: =COUNTIFS(시험용!$B:$B,Graph!AH$3,시험용!$CB:$CB,Graph!$AC7) -> 1 | AI7: =COUNTIFS(시험용!$B:$B,Graph!AI$3,시험용!$CB:$CB,Graph!$AC7) -> 0 | AJ7: =COUNTIFS(시험용!$B:$B,Graph!AJ$3,시험용!$CB:$CB,Graph!$AC7) -> 1 | AK7: =COUNTIFS(시험용!$B:$B,Graph!AK$3,시험용!$CB:$CB,Graph!$AC7) -> 0 | AL7: =COUNTIFS(시험용!$B:$B,Graph!AL$3,시험용!$CB:$CB,Graph!$AC7) -> 0 | ... CD7: =COUNTIFS(시험용!$B:$B,Graph!CD$3,시험용!$CB:$CB,Graph!$AC7) -> 0
AB8: =AD8/$AD$12 -> 0.26744186 | AC8: 18 | AD8: =SUM(AE8:CD8) -> 69 | AE8: =COUNTIFS(시험용!$B:$B,Graph!AE$3,시험용!$CB:$CB,Graph!$AC8) -> 1 | AF8: =COUNTIFS(시험용!$B:$B,Graph!AF$3,시험용!$CB:$CB,Graph!$AC8) -> 3 | AG8: =COUNTIFS(시험용!$B:$B,Graph!AG$3,시험용!$CB:$CB,Graph!$AC8) -> 2 | AH8: =COUNTIFS(시험용!$B:$B,Graph!AH$3,시험용!$CB:$CB,Graph!$AC8) -> 1 | AI8: =COUNTIFS(시험용!$B:$B,Graph!AI$3,시험용!$CB:$CB,Graph!$AC8) -> 4 | AJ8: =COUNTIFS(시험용!$B:$B,Graph!AJ$3,시험용!$CB:$CB,Graph!$AC8) -> 3 | AK8: =COUNTIFS(시험용!$B:$B,Graph!AK$3,시험용!$CB:$CB,Graph!$AC8) -> 0 | AL8: =COUNTIFS(시험용!$B:$B,Graph!AL$3,시험용!$CB:$CB,Graph!$AC8) -> 2 | ... CD8: =COUNTIFS(시험용!$B:$B,Graph!CD$3,시험용!$CB:$CB,Graph!$AC8) -> 0
AB9: =AD9/$AD$12 -> 0.18992248 | AC9: 19 | AD9: =SUM(AE9:CD9) -> 49 | AE9: =COUNTIFS(시험용!$B:$B,Graph!AE$3,시험용!$CB:$CB,Graph!$AC9) -> 2 | AF9: =COUNTIFS(시험용!$B:$B,Graph!AF$3,시험용!$CB:$CB,Graph!$AC9) -> 0 | AG9: =COUNTIFS(시험용!$B:$B,Graph!AG$3,시험용!$CB:$CB,Graph!$AC9) -> 0 | AH9: =COUNTIFS(시험용!$B:$B,Graph!AH$3,시험용!$CB:$CB,Graph!$AC9) -> 2 | AI9: =COUNTIFS(시험용!$B:$B,Graph!AI$3,시험용!$CB:$CB,Graph!$AC9) -> 5 | AJ9: =COUNTIFS(시험용!$B:$B,Graph!AJ$3,시험용!$CB:$CB,Graph!$AC9) -> 1 | AK9: =COUNTIFS(시험용!$B:$B,Graph!AK$3,시험용!$CB:$CB,Graph!$AC9) -> 0 | AL9: =COUNTIFS(시험용!$B:$B,Graph!AL$3,시험용!$CB:$CB,Graph!$AC9) -> 0 | ... CD9: =COUNTIFS(시험용!$B:$B,Graph!CD$3,시험용!$CB:$CB,Graph!$AC9) -> 0
AB10: =AD10/$AD$12 -> 0.20155039 | AC10: 20 | AD10: =SUM(AE10:CD10) -> 52 | AE10: =COUNTIFS(시험용!$B:$B,Graph!AE$3,시험용!$CB:$CB,Graph!$AC10) -> 1 | AF10: =COUNTIFS(시험용!$B:$B,Graph!AF$3,시험용!$CB:$CB,Graph!$AC10) -> 4 | AG10: =COUNTIFS(시험용!$B:$B,Graph!AG$3,시험용!$CB:$CB,Graph!$AC10) -> 1 | AH10: =COUNTIFS(시험용!$B:$B,Graph!AH$3,시험용!$CB:$CB,Graph!$AC10) -> 2 | AI10: =COUNTIFS(시험용!$B:$B,Graph!AI$3,시험용!$CB:$CB,Graph!$AC10) -> 3 | AJ10: =COUNTIFS(시험용!$B:$B,Graph!AJ$3,시험용!$CB:$CB,Graph!$AC10) -> 1 | AK10: =COUNTIFS(시험용!$B:$B,Graph!AK$3,시험용!$CB:$CB,Graph!$AC10) -> 0 | AL10: =COUNTIFS(시험용!$B:$B,Graph!AL$3,시험용!$CB:$CB,Graph!$AC10) -> 6 | ... CD10: =COUNTIFS(시험용!$B:$B,Graph!CD$3,시험용!$CB:$CB,Graph!$AC10) -> 0
AB11: =AD11/$AD$12 -> 0.034883721 | AC11: 21 | AD11: =SUM(AE11:CD11) -> 9 | AE11: =COUNTIFS(시험용!$B:$B,Graph!AE$3,시험용!$CB:$CB,Graph!$AC11) -> 0 | AF11: =COUNTIFS(시험용!$B:$B,Graph!AF$3,시험용!$CB:$CB,Graph!$AC11) -> 0 | AG11: =COUNTIFS(시험용!$B:$B,Graph!AG$3,시험용!$CB:$CB,Graph!$AC11) -> 0 | AH11: =COUNTIFS(시험용!$B:$B,Graph!AH$3,시험용!$CB:$CB,Graph!$AC11) -> 1 | AI11: =COUNTIFS(시험용!$B:$B,Graph!AI$3,시험용!$CB:$CB,Graph!$AC11) -> 0 | AJ11: =COUNTIFS(시험용!$B:$B,Graph!AJ$3,시험용!$CB:$CB,Graph!$AC11) -> 0 | AK11: =COUNTIFS(시험용!$B:$B,Graph!AK$3,시험용!$CB:$CB,Graph!$AC11) -> 1 | AL11: =COUNTIFS(시험용!$B:$B,Graph!AL$3,시험용!$CB:$CB,Graph!$AC11) -> 0 | ... CD11: =COUNTIFS(시험용!$B:$B,Graph!CD$3,시험용!$CB:$CB,Graph!$AC11) -> 0
AC12: SUM | AD12: =SUM(AD4:AD11) -> 258 | AE12: =SUM(AE4:AE11) -> 7 | AF12: =SUM(AF4:AF11) -> 7 | AG12: =SUM(AG4:AG11) -> 5 | AH12: =SUM(AH4:AH11) -> 13 | AI12: =SUM(AI4:AI11) -> 14 | AJ12: =SUM(AJ4:AJ11) -> 7 | AK12: =SUM(AK4:AK11) -> 1 | ... CD12: =SUM(CD4:CD11) -> 0
AC15: ◎ 인치별 양시 제조 규격 수
AB16: Portion | AC16: DOT | AD16: SUB | AE16: 1 | AF16: 2 | AG16: 3 | AH16: 4 | AI16: 5 | AJ16: 6 | AK16: 7 | AL16: 8 | AM16: 9 | AN16: 10 | AO16: 11 | AP16: 12 | AQ16: 13 | AR16: 14 | AS16: 15 | AT16: 16 | AU16: 17 | AV16: 18 | AW16: 19 | AX16: 20 | AY16: 21 | AZ16: 22 | BA16: 23 | BB16: 24 | BC16: 25 | BD16: 26 | BE16: 27 | BF16: 28 | BG16: 29 | BH16: 30 | BI16: 31 | BJ16: 32 | BK16: 33 | BL16: 34 | BM16: 35 | BN16: 36 | BO16: 37 | BP16: 38 | BQ16: 39 | BR16: 40 | BS16: 41 | BT16: 42 | BU16: 43 | BV16: 44 | BW16: 45 | BX16: 46 | BY16: 47 | BZ16: 48 | CA16: 49 | CB16: 50 | CC16: 51 | CD16: 52
AB17: =AD17/$AD$25 -> 0.019607843 | AC17: 14 | AD17: =SUM(AE17:CD17) -> 2 | AE17: =COUNTIFS(양시!$A:$A,Graph!AE$16,양시!$CE:$CE,Graph!$AC17) -> 0 | AF17: =COUNTIFS(양시!$A:$A,Graph!AF$16,양시!$CE:$CE,Graph!$AC17) -> 0 | AG17: =COUNTIFS(양시!$A:$A,Graph!AG$16,양시!$CE:$CE,Graph!$AC17) -> 0 | AH17: =COUNTIFS(양시!$A:$A,Graph!AH$16,양시!$CE:$CE,Graph!$AC17) -> 0 | AI17: =COUNTIFS(양시!$A:$A,Graph!AI$16,양시!$CE:$CE,Graph!$AC17) -> 0 | AJ17: =COUNTIFS(양시!$A:$A,Graph!AJ$16,양시!$CE:$CE,Graph!$AC17) -> 0 | AK17: =COUNTIFS(양시!$A:$A,Graph!AK$16,양시!$CE:$CE,Graph!$AC17) -> 0 | AL17: =COUNTIFS(양시!$A:$A,Graph!AL$16,양시!$CE:$CE,Graph!$AC17) -> 0 | ... CD17: =COUNTIFS(양시!$A:$A,Graph!CD$16,양시!$CE:$CE,Graph!$AC17) -> 0
AB18: =AD18/$AD$25 -> 0.078431373 | AC18: 15 | AD18: =SUM(AE18:CD18) -> 8 | AE18: =COUNTIFS(양시!$A:$A,Graph!AE$16,양시!$CE:$CE,Graph!$AC18) -> 3 | AF18: =COUNTIFS(양시!$A:$A,Graph!AF$16,양시!$CE:$CE,Graph!$AC18) -> 0 | AG18: =COUNTIFS(양시!$A:$A,Graph!AG$16,양시!$CE:$CE,Graph!$AC18) -> 0 | AH18: =COUNTIFS(양시!$A:$A,Graph!AH$16,양시!$CE:$CE,Graph!$AC18) -> 1 | AI18: =COUNTIFS(양시!$A:$A,Graph!AI$16,양시!$CE:$CE,Graph!$AC18) -> 0 | AJ18: =COUNTIFS(양시!$A:$A,Graph!AJ$16,양시!$CE:$CE,Graph!$AC18) -> 0 | AK18: =COUNTIFS(양시!$A:$A,Graph!AK$16,양시!$CE:$CE,Graph!$AC18) -> 1 | AL18: =COUNTIFS(양시!$A:$A,Graph!AL$16,양시!$CE:$CE,Graph!$AC18) -> 1 | ... CD18: =COUNTIFS(양시!$A:$A,Graph!CD$16,양시!$CE:$CE,Graph!$AC18) -> 0
AB19: =AD19/$AD$25 -> 0.16666667 | AC19: 16 | AD19: =SUM(AE19:CD19) -> 17 | AE19: =COUNTIFS(양시!$A:$A,Graph!AE$16,양시!$CE:$CE,Graph!$AC19) -> 0 | AF19: =COUNTIFS(양시!$A:$A,Graph!AF$16,양시!$CE:$CE,Graph!$AC19) -> 0 | AG19: =COUNTIFS(양시!$A:$A,Graph!AG$16,양시!$CE:$CE,Graph!$AC19) -> 1 | AH19: =COUNTIFS(양시!$A:$A,Graph!AH$16,양시!$CE:$CE,Graph!$AC19) -> 0 | AI19: =COUNTIFS(양시!$A:$A,Graph!AI$16,양시!$CE:$CE,Graph!$AC19) -> 3 | AJ19: =COUNTIFS(양시!$A:$A,Graph!AJ$16,양시!$CE:$CE,Graph!$AC19) -> 0 | AK19: =COUNTIFS(양시!$A:$A,Graph!AK$16,양시!$CE:$CE,Graph!$AC19) -> 1 | AL19: =COUNTIFS(양시!$A:$A,Graph!AL$16,양시!$CE:$CE,Graph!$AC19) -> 2 | ... CD19: =COUNTIFS(양시!$A:$A,Graph!CD$16,양시!$CE:$CE,Graph!$AC19) -> 0
AB20: =AD20/$AD$25 -> 0.039215686 | AC20: 17 | AD20: =SUM(AE20:CD20) -> 4 | AE20: =COUNTIFS(양시!$A:$A,Graph!AE$16,양시!$CE:$CE,Graph!$AC20) -> 0 | AF20: =COUNTIFS(양시!$A:$A,Graph!AF$16,양시!$CE:$CE,Graph!$AC20) -> 0 | AG20: =COUNTIFS(양시!$A:$A,Graph!AG$16,양시!$CE:$CE,Graph!$AC20) -> 0 | AH20: =COUNTIFS(양시!$A:$A,Graph!AH$16,양시!$CE:$CE,Graph!$AC20) -> 0 | AI20: =COUNTIFS(양시!$A:$A,Graph!AI$16,양시!$CE:$CE,Graph!$AC20) -> 1 | AJ20: =COUNTIFS(양시!$A:$A,Graph!AJ$16,양시!$CE:$CE,Graph!$AC20) -> 1 | AK20: =COUNTIFS(양시!$A:$A,Graph!AK$16,양시!$CE:$CE,Graph!$AC20) -> 0 | AL20: =COUNTIFS(양시!$A:$A,Graph!AL$16,양시!$CE:$CE,Graph!$AC20) -> 0 | ... CD20: =COUNTIFS(양시!$A:$A,Graph!CD$16,양시!$CE:$CE,Graph!$AC20) -> 0
AB21: =AD21/$AD$25 -> 0.24509804 | AC21: 18 | AD21: =SUM(AE21:CD21) -> 25 | AE21: =COUNTIFS(양시!$A:$A,Graph!AE$16,양시!$CE:$CE,Graph!$AC21) -> 1 | AF21: =COUNTIFS(양시!$A:$A,Graph!AF$16,양시!$CE:$CE,Graph!$AC21) -> 0 | AG21: =COUNTIFS(양시!$A:$A,Graph!AG$16,양시!$CE:$CE,Graph!$AC21) -> 1 | AH21: =COUNTIFS(양시!$A:$A,Graph!AH$16,양시!$CE:$CE,Graph!$AC21) -> 0 | AI21: =COUNTIFS(양시!$A:$A,Graph!AI$16,양시!$CE:$CE,Graph!$AC21) -> 3 | AJ21: =COUNTIFS(양시!$A:$A,Graph!AJ$16,양시!$CE:$CE,Graph!$AC21) -> 1 | AK21: =COUNTIFS(양시!$A:$A,Graph!AK$16,양시!$CE:$CE,Graph!$AC21) -> 0 | AL21: =COUNTIFS(양시!$A:$A,Graph!AL$16,양시!$CE:$CE,Graph!$AC21) -> 3 | ... CD21: =COUNTIFS(양시!$A:$A,Graph!CD$16,양시!$CE:$CE,Graph!$AC21) -> 0
AB22: =AD22/$AD$25 -> 0.14705882 | AC22: 19 | AD22: =SUM(AE22:CD22) -> 15 | AE22: =COUNTIFS(양시!$A:$A,Graph!AE$16,양시!$CE:$CE,Graph!$AC22) -> 2 | AF22: =COUNTIFS(양시!$A:$A,Graph!AF$16,양시!$CE:$CE,Graph!$AC22) -> 0 | AG22: =COUNTIFS(양시!$A:$A,Graph!AG$16,양시!$CE:$CE,Graph!$AC22) -> 1 | AH22: =COUNTIFS(양시!$A:$A,Graph!AH$16,양시!$CE:$CE,Graph!$AC22) -> 3 | AI22: =COUNTIFS(양시!$A:$A,Graph!AI$16,양시!$CE:$CE,Graph!$AC22) -> 0 | AJ22: =COUNTIFS(양시!$A:$A,Graph!AJ$16,양시!$CE:$CE,Graph!$AC22) -> 0 | AK22: =COUNTIFS(양시!$A:$A,Graph!AK$16,양시!$CE:$CE,Graph!$AC22) -> 0 | AL22: =COUNTIFS(양시!$A:$A,Graph!AL$16,양시!$CE:$CE,Graph!$AC22) -> 0 | ... CD22: =COUNTIFS(양시!$A:$A,Graph!CD$16,양시!$CE:$CE,Graph!$AC22) -> 0
AB23: =AD23/$AD$25 -> 0.26470588 | AC23: 20 | AD23: =SUM(AE23:CD23) -> 27 | AE23: =COUNTIFS(양시!$A:$A,Graph!AE$16,양시!$CE:$CE,Graph!$AC23) -> 1 | AF23: =COUNTIFS(양시!$A:$A,Graph!AF$16,양시!$CE:$CE,Graph!$AC23) -> 0 | AG23: =COUNTIFS(양시!$A:$A,Graph!AG$16,양시!$CE:$CE,Graph!$AC23) -> 3 | AH23: =COUNTIFS(양시!$A:$A,Graph!AH$16,양시!$CE:$CE,Graph!$AC23) -> 2 | AI23: =COUNTIFS(양시!$A:$A,Graph!AI$16,양시!$CE:$CE,Graph!$AC23) -> 1 | AJ23: =COUNTIFS(양시!$A:$A,Graph!AJ$16,양시!$CE:$CE,Graph!$AC23) -> 2 | AK23: =COUNTIFS(양시!$A:$A,Graph!AK$16,양시!$CE:$CE,Graph!$AC23) -> 1 | AL23: =COUNTIFS(양시!$A:$A,Graph!AL$16,양시!$CE:$CE,Graph!$AC23) -> 2 | ... CD23: =COUNTIFS(양시!$A:$A,Graph!CD$16,양시!$CE:$CE,Graph!$AC23) -> 0
AB24: =AD24/$AD$25 -> 0.039215686 | AC24: 21 | AD24: =SUM(AE24:CD24) -> 4 | AE24: =COUNTIFS(양시!$A:$A,Graph!AE$16,양시!$CE:$CE,Graph!$AC24) -> 1 | AF24: =COUNTIFS(양시!$A:$A,Graph!AF$16,양시!$CE:$CE,Graph!$AC24) -> 0 | AG24: =COUNTIFS(양시!$A:$A,Graph!AG$16,양시!$CE:$CE,Graph!$AC24) -> 1 | AH24: =COUNTIFS(양시!$A:$A,Graph!AH$16,양시!$CE:$CE,Graph!$AC24) -> 0 | AI24: =COUNTIFS(양시!$A:$A,Graph!AI$16,양시!$CE:$CE,Graph!$AC24) -> 0 | AJ24: =COUNTIFS(양시!$A:$A,Graph!AJ$16,양시!$CE:$CE,Graph!$AC24) -> 1 | AK24: =COUNTIFS(양시!$A:$A,Graph!AK$16,양시!$CE:$CE,Graph!$AC24) -> 0 | AL24: =COUNTIFS(양시!$A:$A,Graph!AL$16,양시!$CE:$CE,Graph!$AC24) -> 0 | ... CD24: =COUNTIFS(양시!$A:$A,Graph!CD$16,양시!$CE:$CE,Graph!$AC24) -> 0
AC25: SUM | AD25: =SUM(AD17:AD24) -> 102 | AE25: =SUM(AE17:AE24) -> 8 | AF25: =SUM(AF17:AF24) -> 0 | AG25: =SUM(AG17:AG24) -> 7 | AH25: =SUM(AH17:AH24) -> 6 | AI25: =SUM(AI17:AI24) -> 8 | AJ25: =SUM(AJ17:AJ24) -> 5 | AK25: =SUM(AK17:AK24) -> 3 | ... CD25: =SUM(CD17:CD24) -> 0
AC28: ※ 시험용 목적별 요청 수량
AB29: Portion | AC29: DOT | AD29: SUB | AE29: 1 | AF29: 2 | AG29: 3 | AH29: 4 | AI29: 5 | AJ29: 6 | AK29: 7 | AL29: 8 | AM29: 9 | AN29: 10 | AO29: 11 | AP29: 12 | AQ29: 13 | AR29: 14 | AS29: 15 | AT29: 16 | AU29: 17 | AV29: 18 | AW29: 19 | AX29: 20 | AY29: 21 | AZ29: 22 | BA29: 23 | BB29: 24 | BC29: 25 | BD29: 26 | BE29: 27 | BF29: 28 | BG29: 29 | BH29: 30 | BI29: 31 | BJ29: 32 | BK29: 33 | BL29: 34 | BM29: 35 | BN29: 36 | BO29: 37 | BP29: 38 | BQ29: 39 | BR29: 40 | BS29: 41 | BT29: 42 | BU29: 43 | BV29: 44 | BW29: 45 | BX29: 46 | BY29: 47 | BZ29: 48 | CA29: 49 | CB29: 50 | CC29: 51 | CD29: 52
AB30: =SUM(AD30:AD33)/SUM(AD30:AD40) -> 0.27804878 | AC30: Cost Optimization | AD30: =SUM(AE30:CD30) -> 12 | AE30: =COUNTIFS(시험요청!$A:$A,Graph!AE$29,시험요청!$AQ:$AQ,Graph!$AC30) -> 0 | AF30: =COUNTIFS(시험요청!$A:$A,Graph!AF$29,시험요청!$AQ:$AQ,Graph!$AC30) -> 0 | AG30: =COUNTIFS(시험요청!$A:$A,Graph!AG$29,시험요청!$AQ:$AQ,Graph!$AC30) -> 0 | AH30: =COUNTIFS(시험요청!$A:$A,Graph!AH$29,시험요청!$AQ:$AQ,Graph!$AC30) -> 3 | AI30: =COUNTIFS(시험요청!$A:$A,Graph!AI$29,시험요청!$AQ:$AQ,Graph!$AC30) -> 1 | AJ30: =COUNTIFS(시험요청!$A:$A,Graph!AJ$29,시험요청!$AQ:$AQ,Graph!$AC30) -> 0 | AK30: =COUNTIFS(시험요청!$A:$A,Graph!AK$29,시험요청!$AQ:$AQ,Graph!$AC30) -> 0 | AL30: =COUNTIFS(시험요청!$A:$A,Graph!AL$29,시험요청!$AQ:$AQ,Graph!$AC30) -> 0 | ... CD30: =COUNTIFS(시험요청!$A:$A,Graph!CD$29,시험요청!$AQ:$AQ,Graph!$AC30) -> 0
AC31: New Technology | AD31: =SUM(AE31:CD31) -> 16 | AE31: =COUNTIFS(시험요청!$A:$A,Graph!AE$29,시험요청!$AQ:$AQ,Graph!$AC31) -> 0 | AF31: =COUNTIFS(시험요청!$A:$A,Graph!AF$29,시험요청!$AQ:$AQ,Graph!$AC31) -> 0 | AG31: =COUNTIFS(시험요청!$A:$A,Graph!AG$29,시험요청!$AQ:$AQ,Graph!$AC31) -> 0 | AH31: =COUNTIFS(시험요청!$A:$A,Graph!AH$29,시험요청!$AQ:$AQ,Graph!$AC31) -> 0 | AI31: =COUNTIFS(시험요청!$A:$A,Graph!AI$29,시험요청!$AQ:$AQ,Graph!$AC31) -> 0 | AJ31: =COUNTIFS(시험요청!$A:$A,Graph!AJ$29,시험요청!$AQ:$AQ,Graph!$AC31) -> 0 | AK31: =COUNTIFS(시험요청!$A:$A,Graph!AK$29,시험요청!$AQ:$AQ,Graph!$AC31) -> 0 | AL31: =COUNTIFS(시험요청!$A:$A,Graph!AL$29,시험요청!$AQ:$AQ,Graph!$AC31) -> 0 | ... CD31: =COUNTIFS(시험요청!$A:$A,Graph!CD$29,시험요청!$AQ:$AQ,Graph!$AC31) -> 0
AC32: Quality Improvement | AD32: =SUM(AE32:CD32) -> 33 | AE32: =COUNTIFS(시험요청!$A:$A,Graph!AE$29,시험요청!$AQ:$AQ,Graph!$AC32) -> 0 | AF32: =COUNTIFS(시험요청!$A:$A,Graph!AF$29,시험요청!$AQ:$AQ,Graph!$AC32) -> 0 | AG32: =COUNTIFS(시험요청!$A:$A,Graph!AG$29,시험요청!$AQ:$AQ,Graph!$AC32) -> 0 | AH32: =COUNTIFS(시험요청!$A:$A,Graph!AH$29,시험요청!$AQ:$AQ,Graph!$AC32) -> 0 | AI32: =COUNTIFS(시험요청!$A:$A,Graph!AI$29,시험요청!$AQ:$AQ,Graph!$AC32) -> 2 | AJ32: =COUNTIFS(시험요청!$A:$A,Graph!AJ$29,시험요청!$AQ:$AQ,Graph!$AC32) -> 2 | AK32: =COUNTIFS(시험요청!$A:$A,Graph!AK$29,시험요청!$AQ:$AQ,Graph!$AC32) -> 1 | AL32: =COUNTIFS(시험요청!$A:$A,Graph!AL$29,시험요청!$AQ:$AQ,Graph!$AC32) -> 1 | ... CD32: =COUNTIFS(시험요청!$A:$A,Graph!CD$29,시험요청!$AQ:$AQ,Graph!$AC32) -> 0
AC33: Research | AD33: =SUM(AE33:CD33) -> 53 | AE33: =COUNTIFS(시험요청!$A:$A,Graph!AE$29,시험요청!$AQ:$AQ,Graph!$AC33) -> 0 | AF33: =COUNTIFS(시험요청!$A:$A,Graph!AF$29,시험요청!$AQ:$AQ,Graph!$AC33) -> 0 | AG33: =COUNTIFS(시험요청!$A:$A,Graph!AG$29,시험요청!$AQ:$AQ,Graph!$AC33) -> 0 | AH33: =COUNTIFS(시험요청!$A:$A,Graph!AH$29,시험요청!$AQ:$AQ,Graph!$AC33) -> 0 | AI33: =COUNTIFS(시험요청!$A:$A,Graph!AI$29,시험요청!$AQ:$AQ,Graph!$AC33) -> 2 | AJ33: =COUNTIFS(시험요청!$A:$A,Graph!AJ$29,시험요청!$AQ:$AQ,Graph!$AC33) -> 2 | AK33: =COUNTIFS(시험요청!$A:$A,Graph!AK$29,시험요청!$AQ:$AQ,Graph!$AC33) -> 0 | AL33: =COUNTIFS(시험요청!$A:$A,Graph!AL$29,시험요청!$AQ:$AQ,Graph!$AC33) -> 3 | ... CD33: =COUNTIFS(시험요청!$A:$A,Graph!CD$29,시험요청!$AQ:$AQ,Graph!$AC33) -> 0
AB34: =SUM(AD34:AD34)/SUM(AD30:AD40) -> 0.18536585 | AC34: Transfer Dev. | AD34: =SUM(AE34:CD34) -> 76 | AE34: =COUNTIFS(시험요청!$A:$A,Graph!AE$29,시험요청!$AQ:$AQ,Graph!$AC34) -> 6 | AF34: =COUNTIFS(시험요청!$A:$A,Graph!AF$29,시험요청!$AQ:$AQ,Graph!$AC34) -> 4 | AG34: =COUNTIFS(시험요청!$A:$A,Graph!AG$29,시험요청!$AQ:$AQ,Graph!$AC34) -> 5 | AH34: =COUNTIFS(시험요청!$A:$A,Graph!AH$29,시험요청!$AQ:$AQ,Graph!$AC34) -> 3 | AI34: =COUNTIFS(시험요청!$A:$A,Graph!AI$29,시험요청!$AQ:$AQ,Graph!$AC34) -> 3 | AJ34: =COUNTIFS(시험요청!$A:$A,Graph!AJ$29,시험요청!$AQ:$AQ,Graph!$AC34) -> 3 | AK34: =COUNTIFS(시험요청!$A:$A,Graph!AK$29,시험요청!$AQ:$AQ,Graph!$AC34) -> 2 | AL34: =COUNTIFS(시험요청!$A:$A,Graph!AL$29,시험요청!$AQ:$AQ,Graph!$AC34) -> 4 | ... CD34: =COUNTIFS(시험요청!$A:$A,Graph!CD$29,시험요청!$AQ:$AQ,Graph!$AC34) -> 0
AB35: =SUM(AD35:AD36)/SUM(AD30:AD40) -> 0.33658537 | AC35: Expand | AD35: =SUM(AE35:CD35) -> 118 | AE35: =COUNTIFS(시험요청!$A:$A,Graph!AE$29,시험요청!$AQ:$AQ,Graph!$AC35) -> 10 | AF35: =COUNTIFS(시험요청!$A:$A,Graph!AF$29,시험요청!$AQ:$AQ,Graph!$AC35) -> 9 | AG35: =COUNTIFS(시험요청!$A:$A,Graph!AG$29,시험요청!$AQ:$AQ,Graph!$AC35) -> 2 | AH35: =COUNTIFS(시험요청!$A:$A,Graph!AH$29,시험요청!$AQ:$AQ,Graph!$AC35) -> 4 | AI35: =COUNTIFS(시험요청!$A:$A,Graph!AI$29,시험요청!$AQ:$AQ,Graph!$AC35) -> 3 | AJ35: =COUNTIFS(시험요청!$A:$A,Graph!AJ$29,시험요청!$AQ:$AQ,Graph!$AC35) -> 3 | AK35: =COUNTIFS(시험요청!$A:$A,Graph!AK$29,시험요청!$AQ:$AQ,Graph!$AC35) -> 3 | AL35: =COUNTIFS(시험요청!$A:$A,Graph!AL$29,시험요청!$AQ:$AQ,Graph!$AC35) -> 6 | ... CD35: =COUNTIFS(시험요청!$A:$A,Graph!CD$29,시험요청!$AQ:$AQ,Graph!$AC35) -> 0
AC36: Model Dev. | AD36: =SUM(AE36:CD36) -> 20 | AE36: =COUNTIFS(시험요청!$A:$A,Graph!AE$29,시험요청!$AQ:$AQ,Graph!$AC36) -> 1 | AF36: =COUNTIFS(시험요청!$A:$A,Graph!AF$29,시험요청!$AQ:$AQ,Graph!$AC36) -> 1 | AG36: =COUNTIFS(시험요청!$A:$A,Graph!AG$29,시험요청!$AQ:$AQ,Graph!$AC36) -> 0 | AH36: =COUNTIFS(시험요청!$A:$A,Graph!AH$29,시험요청!$AQ:$AQ,Graph!$AC36) -> 1 | AI36: =COUNTIFS(시험요청!$A:$A,Graph!AI$29,시험요청!$AQ:$AQ,Graph!$AC36) -> 2 | AJ36: =COUNTIFS(시험요청!$A:$A,Graph!AJ$29,시험요청!$AQ:$AQ,Graph!$AC36) -> 1 | AK36: =COUNTIFS(시험요청!$A:$A,Graph!AK$29,시험요청!$AQ:$AQ,Graph!$AC36) -> 0 | AL36: =COUNTIFS(시험요청!$A:$A,Graph!AL$29,시험요청!$AQ:$AQ,Graph!$AC36) -> 3 | ... CD36: =COUNTIFS(시험요청!$A:$A,Graph!CD$29,시험요청!$AQ:$AQ,Graph!$AC36) -> 0
AB37: =SUM(AD37:AD38)/SUM(AD30:AD40) -> 0.048780488 | AC37: Magazine Test | AD37: =SUM(AE37:CD37) -> 1 | AE37: =COUNTIFS(시험요청!$A:$A,Graph!AE$29,시험요청!$AQ:$AQ,Graph!$AC37) -> 0 | AF37: =COUNTIFS(시험요청!$A:$A,Graph!AF$29,시험요청!$AQ:$AQ,Graph!$AC37) -> 0 | AG37: =COUNTIFS(시험요청!$A:$A,Graph!AG$29,시험요청!$AQ:$AQ,Graph!$AC37) -> 0 | AH37: =COUNTIFS(시험요청!$A:$A,Graph!AH$29,시험요청!$AQ:$AQ,Graph!$AC37) -> 0 | AI37: =COUNTIFS(시험요청!$A:$A,Graph!AI$29,시험요청!$AQ:$AQ,Graph!$AC37) -> 0 | AJ37: =COUNTIFS(시험요청!$A:$A,Graph!AJ$29,시험요청!$AQ:$AQ,Graph!$AC37) -> 0 | AK37: =COUNTIFS(시험요청!$A:$A,Graph!AK$29,시험요청!$AQ:$AQ,Graph!$AC37) -> 0 | AL37: =COUNTIFS(시험요청!$A:$A,Graph!AL$29,시험요청!$AQ:$AQ,Graph!$AC37) -> 0 | ... CD37: =COUNTIFS(시험요청!$A:$A,Graph!CD$29,시험요청!$AQ:$AQ,Graph!$AC37) -> 0
AC38: OE | AD38: =SUM(AE38:CD38) -> 19 | AE38: =COUNTIFS(시험요청!$A:$A,Graph!AE$29,시험요청!$AQ:$AQ,Graph!$AC38) -> 0 | AF38: =COUNTIFS(시험요청!$A:$A,Graph!AF$29,시험요청!$AQ:$AQ,Graph!$AC38) -> 0 | AG38: =COUNTIFS(시험요청!$A:$A,Graph!AG$29,시험요청!$AQ:$AQ,Graph!$AC38) -> 0 | AH38: =COUNTIFS(시험요청!$A:$A,Graph!AH$29,시험요청!$AQ:$AQ,Graph!$AC38) -> 3 | AI38: =COUNTIFS(시험요청!$A:$A,Graph!AI$29,시험요청!$AQ:$AQ,Graph!$AC38) -> 0 | AJ38: =COUNTIFS(시험요청!$A:$A,Graph!AJ$29,시험요청!$AQ:$AQ,Graph!$AC38) -> 0 | AK38: =COUNTIFS(시험요청!$A:$A,Graph!AK$29,시험요청!$AQ:$AQ,Graph!$AC38) -> 0 | AL38: =COUNTIFS(시험요청!$A:$A,Graph!AL$29,시험요청!$AQ:$AQ,Graph!$AC38) -> 1 | ... CD38: =COUNTIFS(시험요청!$A:$A,Graph!CD$29,시험요청!$AQ:$AQ,Graph!$AC38) -> 0
AB39: =AD39/SUM(AD30:AD40) -> 0.15121951 | AC39: Racing | AD39: =SUM(AE39:CD39) -> 62 | AE39: =COUNTIFS(시험요청!$A:$A,Graph!AE$29,시험요청!$AQ:$AQ,Graph!$AC39) -> 0 | AF39: =COUNTIFS(시험요청!$A:$A,Graph!AF$29,시험요청!$AQ:$AQ,Graph!$AC39) -> 2 | AG39: =COUNTIFS(시험요청!$A:$A,Graph!AG$29,시험요청!$AQ:$AQ,Graph!$AC39) -> 0 | AH39: =COUNTIFS(시험요청!$A:$A,Graph!AH$29,시험요청!$AQ:$AQ,Graph!$AC39) -> 0 | AI39: =COUNTIFS(시험요청!$A:$A,Graph!AI$29,시험요청!$AQ:$AQ,Graph!$AC39) -> 4 | AJ39: =COUNTIFS(시험요청!$A:$A,Graph!AJ$29,시험요청!$AQ:$AQ,Graph!$AC39) -> 0 | AK39: =COUNTIFS(시험요청!$A:$A,Graph!AK$29,시험요청!$AQ:$AQ,Graph!$AC39) -> 0 | AL39: =COUNTIFS(시험요청!$A:$A,Graph!AL$29,시험요청!$AQ:$AQ,Graph!$AC39) -> 0 | ... CD39: =COUNTIFS(시험요청!$A:$A,Graph!CD$29,시험요청!$AQ:$AQ,Graph!$AC39) -> 0
AB40: =AD40/SUM(AD30:AD40) -> 0 | AC40: TBR | AD40: =SUM(AE40:CD40) -> 0 | AE40: =TBR!D2 -> 0 | AF40: =TBR!E2 -> 0 | AG40: =TBR!F2 -> 0 | AH40: =TBR!G2 -> 0 | AI40: =TBR!H2 -> 0 | AJ40: =TBR!I2 -> 0 | AK40: =TBR!J2 -> 0 | AL40: =TBR!K2 -> 0 | ... CD40: =TBR!BC2 -> 0
U43: =U44/R44 -> 0.71428571 | AC43: ※ 시험용 목적별 반영 수량
N44: ※ DOT = | O44: 23 | Q44: 요청 = | R44: =SUM(Z52:Z57) -> 14 | T44: 반영 = | U44: =SUM(Z45:Z50) -> 10 | X44: [ 반영 ] | AB44: Portion | AC44: DOT | AD44: SUB | AE44: 1 | AF44: 2 | AG44: 3 | AH44: 4 | AI44: 5 | AJ44: 6 | AK44: 7 | AL44: 8 | AM44: 9 | AN44: 10 | AO44: 11 | AP44: 12 | AQ44: 13 | AR44: 14 | AS44: 15 | AT44: 16 | AU44: 17 | AV44: 18 | AW44: 19 | AX44: 20 | AY44: 21 | AZ44: 22 | BA44: 23 | BB44: 24 | BC44: 25 | BD44: 26 | BE44: 27 | BF44: 28 | BG44: 29 | BH44: 30 | BI44: 31 | BJ44: 32 | BK44: 33 | BL44: 34 | BM44: 35 | BN44: 36 | BO44: 37 | BP44: 38 | BQ44: 39 | BR44: 40 | BS44: 41 | BT44: 42 | BU44: 43 | BV44: 44 | BW44: 45 | BX44: 46 | BY44: 47 | BZ44: 48 | CA44: 49 | CB44: 50 | CC44: 51 | CD44: 52
O45: 29 | X45: Qaulity | Z45: =IFERROR(HLOOKUP($O$44,$AE$44:$CD$55,2,FALSE),"")+IFERROR(HLOOKUP($O$44,$AE$44:$CD$55,3,FALSE),"")+IFERROR(HLOOKUP($O$44,$AE$44:$CD$55,4,FALSE),"")+IFERROR(HLOOKUP($O$44,$AE$44:$CD$55,5,FALSE),"") -> 3 | AB45: =SUM(AD45:AD48)/SUM(AD45:AD55) -> 0.26037736 | AC45: Cost Optimization | AD45: =SUM(AE45:CD45) -> 7 | AE45: =COUNTIFS(시험요청!$A:$A,Graph!AE$44,시험요청!$AQ:$AQ,Graph!$AC45,시험요청!$EW:$EW,"0") -> 0 | AF45: =COUNTIFS(시험요청!$A:$A,Graph!AF$44,시험요청!$AQ:$AQ,Graph!$AC45,시험요청!$EW:$EW,"0") -> 0 | AG45: =COUNTIFS(시험요청!$A:$A,Graph!AG$44,시험요청!$AQ:$AQ,Graph!$AC45,시험요청!$EW:$EW,"0") -> 0 | AH45: =COUNTIFS(시험요청!$A:$A,Graph!AH$44,시험요청!$AQ:$AQ,Graph!$AC45,시험요청!$EW:$EW,"0") -> 2 | AI45: =COUNTIFS(시험요청!$A:$A,Graph!AI$44,시험요청!$AQ:$AQ,Graph!$AC45,시험요청!$EW:$EW,"0") -> 1 | AJ45: =COUNTIFS(시험요청!$A:$A,Graph!AJ$44,시험요청!$AQ:$AQ,Graph!$AC45,시험요청!$EW:$EW,"0") -> 0 | AK45: =COUNTIFS(시험요청!$A:$A,Graph!AK$44,시험요청!$AQ:$AQ,Graph!$AC45,시험요청!$EW:$EW,"0") -> 0 | AL45: =COUNTIFS(시험요청!$A:$A,Graph!AL$44,시험요청!$AQ:$AQ,Graph!$AC45,시험요청!$EW:$EW,"0") -> 0 | ... CD45: =COUNTIFS(시험요청!$A:$A,Graph!CD$44,시험요청!$AQ:$AQ,Graph!$AC45,시험요청!$EW:$EW,"0") -> 0
X46: Transfer | Z46: =IFERROR(HLOOKUP($O$44,$AE$44:$CD$55,6,FALSE),"") -> 1 | AC46: New Technology | AD46: =SUM(AE46:CD46) -> 11 | AE46: =COUNTIFS(시험요청!$A:$A,Graph!AE$44,시험요청!$AQ:$AQ,Graph!$AC46,시험요청!$EW:$EW,"0") -> 0 | AF46: =COUNTIFS(시험요청!$A:$A,Graph!AF$44,시험요청!$AQ:$AQ,Graph!$AC46,시험요청!$EW:$EW,"0") -> 0 | AG46: =COUNTIFS(시험요청!$A:$A,Graph!AG$44,시험요청!$AQ:$AQ,Graph!$AC46,시험요청!$EW:$EW,"0") -> 0 | AH46: =COUNTIFS(시험요청!$A:$A,Graph!AH$44,시험요청!$AQ:$AQ,Graph!$AC46,시험요청!$EW:$EW,"0") -> 0 | AI46: =COUNTIFS(시험요청!$A:$A,Graph!AI$44,시험요청!$AQ:$AQ,Graph!$AC46,시험요청!$EW:$EW,"0") -> 0 | AJ46: =COUNTIFS(시험요청!$A:$A,Graph!AJ$44,시험요청!$AQ:$AQ,Graph!$AC46,시험요청!$EW:$EW,"0") -> 0 | AK46: =COUNTIFS(시험요청!$A:$A,Graph!AK$44,시험요청!$AQ:$AQ,Graph!$AC46,시험요청!$EW:$EW,"0") -> 0 | AL46: =COUNTIFS(시험요청!$A:$A,Graph!AL$44,시험요청!$AQ:$AQ,Graph!$AC46,시험요청!$EW:$EW,"0") -> 0 | ... CD46: =COUNTIFS(시험요청!$A:$A,Graph!CD$44,시험요청!$AQ:$AQ,Graph!$AC46,시험요청!$EW:$EW,"0") -> 0
...

Sheet 시험용
C1: DOT | D1: 1 | E1: 2 | F1: 3 | G1: 4 | H1: 5 | I1: 6 | J1: 7 | K1: 8 | L1: 9 | M1: 10 | N1: 11 | O1: 12 | P1: 13 | Q1: 14 | R1: 15 | S1: 16 | T1: 17 | U1: 18 | V1: 19 | W1: 20 | X1: 21 | Y1: 22 | Z1: 23 | AA1: 24 | AB1: 25 | AC1: 26 | AD1: 27 | AE1: 28 | AF1: 29 | AG1: 30 | AH1: 31 | AI1: 32 | AJ1: 33 | AK1: 34 | AL1: 35 | AM1: 36 | AN1: 37 | AO1: 38 | AP1: 39 | AQ1: 40 | AR1: 41 | AS1: 42 | AT1: 43 | AU1: 44 | AV1: 45 | AW1: 46 | AX1: 47 | AY1: 48 | AZ1: 49 | BA1: 50 | BB1: 51 | BC1: 52
C2: ECN EA | D2: =COUNTIFS($B:$B,D$1) -> 7 | E2: =COUNTIFS($B:$B,E$1) -> 7 | F2: =COUNTIFS($B:$B,F$1) -> 5 | G2: =COUNTIFS($B:$B,G$1) -> 13 | H2: =COUNTIFS($B:$B,H$1) -> 14 | I2: =COUNTIFS($B:$B,I$1) -> 7 | J2: =COUNTIFS($B:$B,J$1) -> 1 | K2: =COUNTIFS($B:$B,K$1) -> 12 | ... BC2: =COUNTIFS($B:$B,BC$1) -> 0
C3: T/D 신제작 | D3: =COUNTIFS($A:$A,D$1,$AA:$AA,"신제작") -> 4 | E3: =COUNTIFS($A:$A,E$1,$AA:$AA,"신제작") -> 5 | F3: =COUNTIFS($A:$A,F$1,$AA:$AA,"신제작") -> 4 | G3: =COUNTIFS($A:$A,G$1,$AA:$AA,"신제작") -> 5 | H3: =COUNTIFS($A:$A,H$1,$AA:$AA,"신제작") -> 6 | I3: =COUNTIFS($A:$A,I$1,$AA:$AA,"신제작") -> 5 | J3: =COUNTIFS($A:$A,J$1,$AA:$AA,"신제작") -> 1 | K3: =COUNTIFS($A:$A,K$1,$AA:$AA,"신제작") -> 6 | ... BC3: =COUNTIFS($A:$A,BC$1,$AA:$AA,"신제작") -> 0
C4: S/W 신제작 | D4: =COUNTIFS($A:$A,D$1,$AF:$AF,"신제작") -> 5 | E4: =COUNTIFS($A:$A,E$1,$AF:$AF,"신제작") -> 3 | F4: =COUNTIFS($A:$A,F$1,$AF:$AF,"신제작") -> 3 | G4: =COUNTIFS($A:$A,G$1,$AF:$AF,"신제작") -> 4 | H4: =COUNTIFS($A:$A,H$1,$AF:$AF,"신제작") -> 6 | I4: =COUNTIFS($A:$A,I$1,$AF:$AF,"신제작") -> 3 | J4: =COUNTIFS($A:$A,J$1,$AF:$AF,"신제작") -> 1 | K4: =COUNTIFS($A:$A,K$1,$AF:$AF,"신제작") -> 4 | ... BC4: =COUNTIFS($A:$A,BC$1,$AF:$AF,"신제작") -> 0
C5: 시험용 취소 | D5: =COUNTIFS($A:$A,D$1,$S:$S,"X") -> 0 | E5: =COUNTIFS($A:$A,E$1,$S:$S,"X") -> 0 | F5: =COUNTIFS($A:$A,F$1,$S:$S,"X") -> 0 | G5: =COUNTIFS($A:$A,G$1,$S:$S,"X") -> 0 | H5: =COUNTIFS($A:$A,H$1,$S:$S,"X") -> 0 | I5: =COUNTIFS($A:$A,I$1,$S:$S,"X") -> 0 | J5: =COUNTIFS($A:$A,J$1,$S:$S,"X") -> 0 | K5: =COUNTIFS($A:$A,K$1,$S:$S,"X") -> 1 | ... BC5: =COUNTIFS($A:$A,BC$1,$S:$S,"X") -> 0
B7: ="("&SUM(D7:BC7)&")" -> (421) | C7: Spec. EA | D7: =COUNTIFS($A:$A,D$1) -> 7 | E7: =COUNTIFS($A:$A,E$1) -> 7 | F7: =COUNTIFS($A:$A,F$1) -> 5 | G7: =COUNTIFS($A:$A,G$1) -> 15 | H7: =COUNTIFS($A:$A,H$1) -> 23 | I7: =COUNTIFS($A:$A,I$1) -> 15 | J7: =COUNTIFS($A:$A,J$1) -> 1 | K7: =COUNTIFS($A:$A,K$1) -> 19 | ... BC7: =COUNTIFS($A:$A,BC$1) -> 0
B8: ="("&SUM(D8:BC8)&")" -> (7055) | C8: Tire EA | D8: =SUMIFS($R:$R,$A:$A,D$1) -> 86 | E8: =SUMIFS($R:$R,$A:$A,E$1) -> 102 | F8: =SUMIFS($R:$R,$A:$A,F$1) -> 58 | G8: =SUMIFS($R:$R,$A:$A,G$1) -> 298 | H8: =SUMIFS($R:$R,$A:$A,H$1) -> 306 | I8: =SUMIFS($R:$R,$A:$A,I$1) -> 204 | J8: =SUMIFS($R:$R,$A:$A,J$1) -> 14 | K8: =SUMIFS($R:$R,$A:$A,K$1) -> 288 | ... BC8: =SUMIFS($R:$R,$A:$A,BC$1) -> 0
A10: DOT | B10: ECN 수량 파악 | C10: 담당 | D10: R&D | E10: PI | F10: LINE | G10: ECN No. | H10: 제조 특이 사항 | I10: Product | J10: Size | K10: Pattern | L10: PR | M10: T/L | N10: B/W | O10: USE | P10: BR | Q10: Spec No. | R10: EA. | S10: Plan | T10: 성형기 (OE/RE) | U10: ECN Purpose | V10: T/D CTB | W10: T/D SUT | X10: T/D TRW | Y10: T/D Chimney | Z10: T/D Die No | AA10: T/D New/Exist | AB10: T/D Total Width | AC10: S/W BSW | AD10: S/W RIC | AE10: S/W Die No | AF10: S/W New/Exist | AG10: S/W Width | AH10: PA | AI10: Belt Drum Circumference | AJ10: I/L#1 Code | AK10: I/L#1 Width | AL10: I/L#2 Width | AM10: C/C#1 Code | AN10: C/C#1 Rolled | AO10: C/C#1 Width | AP10: C/C#1 Angle | AQ10: C/C#2 Code | AR10: C/C#2 Rolled | AS10: C/C#2 Width | AT10: C/C#2 Angle | AU10: BT#1 Code | AV10: BT#1 Rolled | AW10: BT#1 Width | AX10: BT#1 Angle | AY10: BT#2 Code | AZ10: BT#2 Rolled | BA10: BT#2 Width | BB10: BT#2 Angle | BC10: JLB Rolled | BD10: Side Filling Tape Width | BE10: SRFM Code | BF10: SRFM Width | BG10: SRFM Angle | BH10: Bead Filler Tape Code | BI10: Bead Filler Tape Comp'd | BJ10: Over | BK10: Rim Cushion Sheet Width | BL10: Special Material | BM10: 비고1 | BN10: Inch | BO10: Mold No. | BP10: Bladder Code | BQ10: Curing Time(Old) | BR10: CTR | BS10: 비드 OE | BT10: Bead Code | BU10: Bead Bundle | BV10: Bead Filler | BW10: Bead BIC | BX10: Special Notice | BY10: Mold Ware Status | BZ10: 업체 | CB10: INCH | CC10: ISSUE | CE10: Die 기제작 or 수정
A11: 1 | B11: 1 | C11: RE | D11: 이학진 | E11: 김영광 | F11: DS | G11: 2025121451 | H11: JF0 | I11: 1037783 | J11: 255/50R20V XL | K11: W340A | L11: 4 | M11: L | N11: B | O11: - | P11: HK | Q11: 1 | R11: 14 | S11: 01/05 월 | T11: RE/DS H139 | U11: Expand | V11: P42 | W11: U36 | X11: S25 | Y11: U35 (C) | Z11: DR75045 | AA11: B1004 | AB11: 262 | AC11: S24 | AD11: B89 | AE11: DN69406 | AF11: B1007 | AG11: 150 | AH11: 726 | AI11: 2240 | AJ11: FY25169 | AK11: 480 | AL11: 445 | AM11: FX28696 | AN11: ET10416 | AO11: 600 | AP11: 90 | AQ11: FX27503 | AR11: ET10416 | AS11: 500 | AT11: 90 | AU11: FHB0042 | AV11: ES10262 | AW11: 225 | AX11: 27 | AY11: FX27883 | AZ11: ES10262 | BA11: 215 | BB11: 27 | BC11: ET11001 | BD11: - | BE11: - | BF11: - | BG11: - | BH11: - | BI11: - | BJ11: TREAD | BK11: - | BL11: - | BN11: 20 | BO11: [정규용] 25H87 25H88 | BP11: BG32BU | BQ11: CE09V12 | BR11: 48L | BT11: GU29032 | BU11: GW22189 | BV11: AT235 | BW11: 1626 | BX11: 중량개선 Spec | BY11: Ware Ware | BZ11: HPW | CA11: =A11&"&"&G11 -> 1&2025121451 | CB11: =IFERROR(MID(J11,FIND("R",J11)+1,2),"") -> 20 | CC11: - | CE11: =IFERROR(VLOOKUP(CA11,시험요청!EV:EZ,5,FALSE),"") -> 0
A12: 1 | B12: 1 | C12: RE | D12: 최수빈 | E12: 이준탁 | F12: DS | G12: 2025121816 | H12: JF0 | I12: 1037813 | J12: 235/50R17V XL | K12: W340 | L12: 4 | M12: L | N12: B | O12: - | P12: HK | Q12: 1 | R12: 14 | S12: 01/06 화 | T12: RE/DS H154 | U12: Expand | V12: P47 | W12: U36 | X12: S25 | Y12: U35 (C) | Z12: DR74980 | AA12: B1004 | AB12: 242 | AC12: S24 | AD12: B89 | AE12: DN69440 | AF12: 신제작 | AG12: 140 | AH12: 668 | AI12: 1945 | AJ12: FY24517 | AK12: 440 | AL12: 405 | AM12: FX23123 | AN12: ET20271 | AO12: 550 | AP12: 90 | AQ12: FX23174 | AR12: ET20271 | AS12: 460 | AT12: 90 | AU12: FHB0033 | AV12: ES10262 | AW12: 205 | AX12: 27 | AY12: FX27873 | AZ12: ES10262 | BA12: 195 | BB12: 27 | BC12: ET11001 | BD12: - | BE12: - | BF12: - | BG12: - | BH12: - | BI12: - | BJ12: TREAD | BK12: - | BL12: - | BN12: 17 | BO12: [정규용] 25P53 25P54 | BP12: BE43AI | BQ12: - | BR12: 47M | BT12: GU28137 | BU12: GW21958 | BV12: AT225 | BW12: 1386 | BX12: 168℃ 가류 | BY12: Ware Ware | BZ12: SYT | CA12: =A12&"&"&G12 -> 1&2025121816 | CB12: =IFERROR(MID(J12,FIND("R",J12)+1,2),"") -> 17 | CC12: - | CE12: =IFERROR(VLOOKUP(CA12,시험요청!EV:EZ,5,FALSE),"") -> 0
A13: 1 | B13: 1 | C13: RE | D13: 현재호 | E13: 김노연 | F13: DS | G13: 2025121454 | H13: JF0 | I13: 1037667 | J13: 225/35R19W XL | K13: W340 | L13: 4 | M13: L | N13: B | O13: - | P13: HK | Q13: 1 | R13: 14 | S13: 01/06 화 | T13: RE/DS H131 | U13: Expand | V13: P47 | W13: U36 | X13: S25 | Y13: U35 (C) | Z13: DR75062 | AA13: 신제작 | AB13: 242 | AC13: S24 | AD13: B89 | AE13: DN69429 | AF13: 신제작 | AG13: 85 | AH13: 472 | AI13: 1865 | AJ13: FY25096 | AK13: 350 | AL13: 315 | AM13: FS00809 | AN13: ET10203 | AO13: 410 | AP13: 90 | AQ13: - | AR13: - | AS13: - | AT13: - | AU13: FHB0005 | AV13: ES10262 | AW13: 210 | AX13: 27 | AY13: FX27873 | AZ13: ES10262 | BA13: 195 | BB13: 27 | BC13: ET11001 | BD13: 60 | BE13: - | BF13: - | BG13: - | BH13: - | BI13: - | BJ13: SIDE | BK13: - | BL13: - | BN13: 19 | BO13: [정규용] 25M87 25M88 | BP13: BG25BU | BQ13: CA04Z14 | BR13: 45M | BT13: GU28246 | BU13: GW22186 | BV13: AH210 | BW13: 1542 | BY13: Ware Ware | BZ13: HPW | CA13: =A13&"&"&G13 -> 1&2025121454 | CB13: =IFERROR(MID(J13,FIND("R",J13)+1,2),"") -> 19 | CC13: - | CE13: =IFERROR(VLOOKUP(CA13,시험요청!EV:EZ,5,FALSE),"") -> 0
A14: 1 | B14: 1 | C14: 양산기술 | D14: 최형인 | E14: 이준탁 | F14: DS | G14: 2025122406 | H14: JF505 P2000D/2 | I14: 2022628 | J14: 195/70R15C | K14: RA58 | L14: 8 | M14: L | N14: B | O14: - | P14: HK | Q14: 3 | R14: 10 | S14: 01/08 목 | T14: RE/DS H152 | U14: Transfer Dev. | V14: T95 | W14: U36 | X14: S25 | Y14: U35 (F) | Z14: DR74914 | AA14: B1003 | AB14: 206 | AC14: S24 | AD14: B89 | AE14: DN69272 | AF14: B1005 | AG14: 165 | AH14: 684 | AI14: 1880 | AJ14: FY25628 | AK14: 410 | AL14: 375 | AM14: FW02577 | AN14: ET10135 | AO14: 570 | AP14: 90 | AQ14: - | AR14: - | AS14: - | AT14: - | AU14: FHB0152 | AV14: ES20427 | AW14: 170 | AX14: 27 | AY14: FH23974 | AZ14: ES20427 | BA14: 155 | BB14: 27 | BC14: ET10121 | BD14: - | BE14: - | BF14: - | BG14: - | BH14: DN56899 | BI14: CQB86 | BJ14: TREAD | BK14: - | BL14: P2000D/2 | BN14: 15 | BO14: [정규용] 24Q30 24Q31 | BP14: BD40AI | BQ14: CA02Z15 | BR14: 42M | BT14: GU28633 | BU14: GW56006 | BV14: BB215 | BW14: 1204 | BY14: Ware Ware | BZ14: 혜원 | CA14: =A14&"&"&G14 -> 1&2025122406 | CB14: =IFERROR(MID(J14,FIND("R",J14)+1,2),"") -> 15 | CC14: - | CE14: =IFERROR(VLOOKUP(CA14,시험요청!EV:EZ,5,FALSE),"") -> 0
A15: 1 | B15: 1 | C15: RE | D15: 이병재 | E15: 김상훈 | F15: DM | G15: 2025120465 | H15: JF5 | I15: 2022670 | J15: LT265/70R18 | K15: PC05 | L15: 10 | M15: L | N15: B | O15: - | P15: HK | Q15: 0 | R15: 12 | S15: 01/08 목 | T15: RE/DM H107 | U15: Expand | V15: P95 | W15: U73 | X15: S25 | Y15: - (N) | Z15: DR75058 | AA15: 신제작 | AB15: 262 | AC15: S24 | AD15: B89 | AE15: DN69425 | AF15: 신제작 | AG15: 230 | AH15: 970 | AI15: 2385 | AJ15: FY25559 | AK15: 560 | AL15: 525 | AM15: FR03504 | AN15: ET11006 | AO15: 780 | AP15: 90 | AQ15: FW02375 | AR15: ET11006 | AS15: 590 | AT15: 90 | AU15: FHB0175 | AV15: ES20427 | AW15: 215 | AX15: 24 | AY15: FH24381 | AZ15: ES20427 | BA15: 200 | BB15: 24 | BC15: ET10121 | BD15: - | BE15: - | BF15: - | BG15: - | BH15: DN56899 | BI15: CQB86 | BJ15: TREAD | BK15: 40 | BL15: - | BN15: 18 | BO15: [정규용] 25DH5 25DH6 (신제작중) | BP15: BE45AI | BQ15: 65KJX19 | BR15: 51S | BT15: GU29791 | BU15: GW22184 | BV15: BU118 | BW15: 1475 | BX15: H107 C/C Turn-Up 68% | BY15: Making Making | BZ15: SYT | CA15: =A15&"&"&G15 -> 1&2025120465 | CB15: =IFERROR(MID(J15,FIND("R",J15)+1,2),"") -> 18 | CC15: - | CE15: =IFERROR(VLOOKUP(CA15,시험요청!EV:EZ,5,FALSE),"") -> 0
A16: 1 | B16: 1 | C16: 양산기술 | D16: 임서윤 | E16: 이준탁 | F16: DS | G16: 2025121487 | H16: JF505 | I16: 1028488 | J16: 225/45R17W XL | K16: K135 | L16: 4 | M16: L | N16: B | O16: - | P16: HK | Q16: 0 | R16: 10 | S16: 01/09 금 | T16: RE/DS H142 | U16: Transfer Dev. | V16: P37 | W16: U36 | X16: S25 | Y16: U35 (C) | Z16: DR75068 | AA16: 신제작 | AB16: 244 | AC16: S24 | AD16: B89 | AE16: DN69434 | AF16: 신제작 | AG16: 110 | AH16: 554 | AI16: 1835 | AJ16: FY24849 | AK16: 380 | AL16: 345 | AM16: FD23257 | AN16: ET10203 | AO16: 480 | AP16: 90 | AQ16: - | AR16: - | AS16: - | AT16: - | AU16: FHB0003 | AV16: ES20425 | AW16: 205 | AX16: 27 | AY16: FX26252 | AZ16: ES20425 | BA16: 195 | BB16: 27 | BC16: ET11001 | BD16: - | BE16: - | BF16: - | BG16: - | BH16: - | BI16: - | BJ16: SIDE | BK16: - | BL16: - | BN16: 17 | BO16: [정규용] 20G30 20G31 (개조중, KP, 미반출) | BP16: BE49AI | BQ16: - | BR16: 42M | BT16: GU28198 | BU16: GW21957 | BV16: AT225 | BW16: 1383 | BZ16: 혜원 | CA16: =A16&"&"&G16 -> 1&2025121487 | CB16: =IFERROR(MID(J16,FIND("R",J16)+1,2),"") -> 17 | CC16: - | CE16: =IFERROR(VLOOKUP(CA16,시험요청!EV:EZ,5,FALSE),"") -> 0
A17: 1 | B17: 1 | C17: 양산기술 | D17: 임서윤 | E17: 김상훈 | F17: DS | G17: 2025122398 | H17: JF5 P2000D/2 | I17: 1038787 | J17: 225/55R19V | K17: LH01 | L17: 4 | M17: L | N17: B | O17: - | P17: LF | Q17: 0 | R17: 12 | S17: 01/09 금 | T17: RE/DS H187 | U17: Transfer Dev. | V17: P90 | W17: U33 | X17: S25 | Y17: - (N) | Z17: DR75064 | AA17: 신제작 | AB17: 246 | AC17: S24 | AD17: B89 | AE17: DN69431 | AF17: 신제작 | AG17: 140 | AH17: 668 | AI17: 2135 | AJ17: FY24517 | AK17: 440 | AL17: 405 | AM17: FD24366 | AN17: ET10135 | AO17: 550 | AP17: 90 | AQ17: - | AR17: - | AS17: - | AT17: - | AU17: FHB0288 | AV17: ES10259 | AW17: 200 | AX17: 27 | AY17: FX27989 | AZ17: ES10259 | BA17: 190 | BB17: 27 | BC17: ET10121 | BD17: - | BE17: - | BF17: - | BG17: - | BH17: - | BI17: - | BJ17: SIDE | BK17: - | BL17: P2000D/2 | BN17: 19 | BO17: [정규용] 25EM2 25EM3 (신제작중) | BP17: BG35BU | BQ17: - | BR17: 47M | BT17: GU28155 | BU17: GW22186 | BV17: AT225 | BW17: 1542 | BY17: Making Making | BZ17: HPW | CA17: =A17&"&"&G17 -> 1&2025122398 | CB17: =IFERROR(MID(J17,FIND("R",J17)+1,2),"") -> 19 | CC17: - | CE17: =IFERROR(VLOOKUP(CA17,시험요청!EV:EZ,5,FALSE),"") -> 0
A18: 2 | B18: 2 | C18: RE | D18: 이병재 | E18: 김노연 | F18: DM | G18: 2025120572 | H18: JF5 | I18: 2022682 | J18: LT265/65R18 | K18: PC05 | L18: 10 | M18: L | N18: B | O18: - | P18: HK | Q18: 0 | R18: 12 | S18: 01/12 월 | T18: RE/DM H107 | U18: Expand | V18: P95 | W18: U73 | X18: S25 | Y18: - (N) | Z18: DR75059 | AA18: 신제작 | AB18: 270 | AC18: S24 | AD18: B89 | AE18: DN69144 | AF18: B1005 | AG18: 215 | AH18: 912 | AI18: 2310 | AJ18: FY25503 | AK18: 540 | AL18: 505 | AM18: FR03551 | AN18: ET11006 | AO18: 730 | AP18: 90 | AQ18: FW02587 | AR18: ET11006 | AS18: 570 | AT18: 90 | AU18: FHB0124 | AV18: ES20427 | AW18: 225 | AX18: 24 | AY18: FH24385 | AZ18: ES20427 | BA18: 210 | BB18: 24 | BC18: ET10121 | BD18: - | BE18: - | BF18: - | BG18: - | BH18: DN56899 | BI18: CQB86 | BJ18: TREAD | BK18: 40 | BL18: - | BN18: 18 | BO18: [정규용] 25EK9 25EM1 (신제작중) | BP18: BG20AP | BQ18: CE55Q24 | BR18: 51M | BT18: GU29791 | BU18: GW22184 | BV18: BU118 | BW18: 1475 | BX18: H107 C/C Turn-Up 68% | BY18: Making Making | BZ18: SYT | CA18: =A18&"&"&G18 -> 2&2025120572 | CB18: =IFERROR(MID(J18,FIND("R",J18)+1,2),"") -> 18 | CC18: 성형 먼저 진행, Mold 01/14 입고 PLC Error : 가류 BD 변경 BE58BU | CE18: =IFERROR(VLOOKUP(CA18,시험요청!EV:EZ,5,FALSE),"") -> 0
A19: 2 | B19: 2 | C19: RE | D19: 이병재 | E19: 이준탁 | F19: DM | G19: 2025120456 | H19: JF505 | I19: 1038859 | J19: 275/55R20T | K19: PC05 | L19: 4 | M19: L | N19: B | O19: - | P19: HK | Q19: 0 | R19: 12 | S19: 01/12 월 | T19: RE/DM H101 | U19: Expand | V19: P95 | W19: U33 | X19: S25 | Y19: - (N) | Z19: DR75053 | AA19: 신제작 | AB19: 298 | AC19: S24 | AD19: B89 | AE19: DN69416 | AF19: 신제작 | AG19: 175 | AH19: 834 | AI19: 2365 | AJ19: FY24970 | AK19: 530 | AL19: 495 | AM19: FR03466 | AN19: ET10203 | AO19: 680 | AP19: 90 | AQ19: FD23261 | AR19: ET10203 | AS19: 560 | AT19: 90 | AU19: FHB0522 | AV19: ES20424 | AW19: 250 | AX19: 24 | AY19: FX31676 | AZ19: ES20424 | BA19: 240 | BB19: 24 | BC19: ET10121 | BD19: - | BE19: - | BF19: - | BG19: - | BH19: - | BI19: - | BJ19: SIDE | BK19: 40 | BL19: - | BN19: 20 | BO19: [정규용] 25DH1 25DH2 (신제작중(입고대기중)) | BP19: BG18AN | BQ19: CE09X13 | BR19: 51M | BT19: GU29808 | BU19: GW22189 | BV19: BH245 | BW19: 1626 | BY19: Making Making | BZ19: HPW | CA19: =A19&"&"&G19 -> 2&2025120456 | CB19: =IFERROR(MID(J19,FIND("R",J19)+1,2),"") -> 20 | CC19: - | CE19: =IFERROR(VLOOKUP(CA19,시험요청!EV:EZ,5,FALSE),"") -> 0
A20: 2 | B20: 2 | C20: RE | D20: 이병재 | E20: 이준탁 | F20: DM | G20: 2025120457 | H20: JF505 | I20: 1038860 | J20: 275/60R20T | K20: PC05 | L20: 4 | M20: L | N20: B | O20: - | P20: HK | Q20: 0 | R20: 12 | S20: 01/13 화 | T20: RE/DM H101 | U20: Expand | V20: P95 | W20: U33 | X20: S25 | Y20: - (N) | Z20: DR75034 | AA20: B1001 | AB20: 290 | AC20: S24 | AD20: B89 | AE20: DN68598 | AF20: B1005 | AG20: 200 | AH20: 914 | AI20: 2440 | AJ20: FY25121 | AK20: 560 | AL20: 525 | AM20: FR03970 | AN20: ET10203 | AO20: 710 | AP20: 90 | AQ20: FW00694 | AR20: ET10203 | AS20: 590 | AT20: 90 | AU20: FHB0375 | AV20: ES20424 | AW20: 230 | AX20: 24 | AY20: FX31176 | AZ20: ES20424 | BA20: 220 | BB20: 24 | BC20: ET10121 | BD20: - | BE20: - | BF20: - | BG20: - | BH20: DN56899 | BI20: CQB86 | BJ20: TREAD | BK20: 40 | BL20: - | BN20: 20 | BO20: [정규용] 25DH3 25DH4 (신제작중(입고대기중)) | BP20: BG18AN | BQ20: CE09N14 | BR20: 51S | BT20: GU29287 | BU20: GW22189 | BV20: BH215 | BW20: 1626 | BY20: Making Making | BZ20: HPW | CA20: =A20&"&"&G20 -> 2&2025120457 | CB20: =IFERROR(MID(J20,FIND("R",J20)+1,2),"") -> 20 | CC20: - | CE20: =IFERROR(VLOOKUP(CA20,시험요청!EV:EZ,5,FALSE),"") -> 0
A21: 2 | B21: 2 | C21: RE | D21: 정덕교 | E21: 김상훈 | F21: DS | G21: 2025122989 | H21: JF505 | I21: 1036584 | J21: 235/60R20H XL | K21: IW41A | L21: 4 | M21: L | N21: B | O21: 8 | P21: HK | Q21: 9 | R21: 12 | S21: 01/14 수 | T21: RE/DS H132 | U21: Expand | V21: P94 | W21: U35 | X21: S25 | Y21: - (C) | Z21: DR75065 | AA21: 신제작 | AB21: 238 | AC21: S24 | AD21: B89 | AE21: DN69231 | AF21: B1005 | AG21: 160 | AH21: 746 | AI21: 2320 | AJ21: FY25095 | AK21: 470 | AL21: 435 | AM21: FX30397 | AN21: ET10416 | AO21: 610 | AP21: 90 | AQ21: FX27726 | AR21: ET10416 | AS21: 490 | AT21: 90 | AU21: FHB0033 | AV21: ES10262 | AW21: 205 | AX21: 27 | AY21: FX27884 | AZ21: ES10262 | BA21: 190 | BB21: 27 | BC21: ET10121 | BD21: - | BE21: - | BF21: - | BG21: - | BH21: - | BI21: - | BJ21: TREAD | BK21: - | BL21: - | BN21: 20 | BO21: [정규용] 24S96 24S97 | BP21: BG32BU | BQ21: CE02W17 | BR21: 51M | BT21: GU29315 | BU21: GW22189 | BV21: AH245 | BW21: 1626 | BX21: 2차 양시 NG (DS) 단면 확보 필요 | BY21: Ware Ware | BZ21: 혜원 | CA21: =A21&"&"&G21 -> 2&2025122989 | CB21: =IFERROR(MID(J21,FIND("R",J21)+1,2),"") -> 20 | CC21: - | CE21: =IFERROR(VLOOKUP(CA21,시험요청!EV:EZ,5,FALSE),"") -> 0
A22: 2 | B22: 2 | C22: 양산기술 | D22: 임서윤 | E22: 김노연 | F22: DM | G22: 2025123192 | H22: JF505 | I22: 1022658 | J22: 245/50R20V | K22: H452 | L22: 4 | M22: L | N22: B | O22: H | P22: HK | Q22: 0 | R22: 10 | S22: 01/14 수 | T22: RE/DM H101 | U22: Transfer Dev. | V22: P53 | W22: U36 | X22: S25 | Y22: U35 (C) | Z22: DR75074 | AA22: 신제작 | AB22: 256 | AC22: S24 | AD22: B89 | AE22: DN69445 | AF22: 신제작 | AG22: 145 | AH22: 694 | AI22: 2185 | AJ22: FY24792 | AK22: 450 | AL22: 415 | AM22: FX23798 | AN22: ET20271 | AO22: 590 | AP22: 90 | AQ22: FN00441 | AR22: ET20271 | AS22: 480 | AT22: 90 | AU22: FH23228 | AV22: ES10262 | AW22: 220 | AX22: 27 | AY22: FX27894 | AZ22: ES10262 | BA22: 210 | BB22: 27 | BC22: ET11001 | BD22: 40 | BE22: - | BF22: - | BG22: - | BH22: - | BI22: - | BJ22: SIDE | BK22: - | BL22: - | BN22: 20 | BO22: [정규용] 19N15 19N18 19N19 22965 (개조중, KP) | BP22: BG05BP | BQ22: CE09V11 | BR22: 48L | BT22: GU29455 | BU22: GW22189 | BV22: DT235 | BW22: 1626 | BZ22: 대광 | CA22: =A22&"&"&G22 -> 2&2025123192 | CB22: =IFERROR(MID(J22,FIND("R",J22)+1,2),"") -> 20 | CC22: - | CE22: =IFERROR(VLOOKUP(CA22,시험요청!EV:EZ,5,FALSE),"") -> 0
A23: 2 | B23: 2 | C23: RE | D23: 허유진 | E23: 이준탁 | F23: DP | G23: 2025123699 | H23: JF505 | I23: 1038581 | J23: 280/660R18 | K23: Z207 | L23: 4 | M23: L | N23: B | O23: Q | P23: HK | Q23: 1 | R23: 22 | S23: 01/15 목 | T23: RE/DP H103 | U23: Quality Improvement | V23: F53 | W23: U35 | X23: - | Y23: - (N) | Z23: DR72284 | AA23: B1006 | AB23: 300 | AC23: S26 | AD23: - | AE23: DN69450 | AF23: 신제작 | AG23: 135 | AH23: 0 | AI23: 1946 | AJ23: FA29724 | AK23: 475 | AL23: - | AM23: FX28047 | AN23: ET11040 | AO23: 625 | AP23: 77 | AQ23: FX30608 | AR23: ET11040 | AS23: 460 | AT23: 77 | AU23: FJ22980 | AV23: ES20425 | AW23: 270 | AX23: 33 | AY23: FX31860 | AZ23: ES20425 | BA23: 255 | BB23: 33 | BC23: ET11001 | BD23: - | BE23: - | BF23: - | BG23: - | BH23: - | BI23: - | BJ23: TREAD | BK23: - | BL23: 33도 벨트 | BN23: 18 | BO23: [정규용] 10A16 10A17 | BP23: BE0545 | BQ23: - | BR23: 48M | BT23: GU28798 | BU23: GW22005 | BV23: DH220 | BW23: 1466 | BY23: Ware Ware | BZ23: 대광 | CA23: =A23&"&"&G23 -> 2&2025123699 | CB23: =IFERROR(MID(J23,FIND("R",J23)+1,2),"") -> 18 | CC23: - | CE23: =IFERROR(VLOOKUP(CA23,시험요청!EV:EZ,5,FALSE),"") -> 0
A24: 2 | B24: 2 | C24: RE | D24: 허유진 | E24: 김노연 | F24: DP | G24: 2025123704 | H24: JF505 | I24: 1038585 | J24: 320/710R18 | K24: Z207 | L24: 4 | M24: L | N24: B | O24: Q | P24: HK | Q24: 0 | R24: 22 | S24: 01/15 목 | T24: RE/DP H103 | U24: Quality Improvement | V24: F53 | W24: U35 | X24: - | Y24: - (N) | Z24: DR72282 | AA24: 신제작 | AB24: 354 | AC24: S26 | AD24: - | AE24: DN67305 | AF24: B1006 | AG24: 145 | AH24: 0 | AI24: 2089 | AJ24: - | AK24: - | AL24: - | AM24: FX28035 | AN24: ET11040 | AO24: 720 | AP24: 77 | AQ24: FX30609 | AR24: ET11040 | AS24: 540 | AT24: 77 | AU24: FJ22983 | AV24: ES20425 | AW24: 315 | AX24: 33 | AY24: FX30830 | AZ24: ES20425 | BA24: 300 | BB24: 33 | BC24: ET11001 | BD24: - | BE24: - | BF24: - | BG24: - | BH24: - | BI24: - | BJ24: TREAD | BK24: - | BL24: 33도 벨트 | BN24: 18 | BO24: [정규용] 21695 21696 | BP24: BE0545 | BQ24: - | BR24: 48M | BT24: GU26850 | BU24: GW22005 | BV24: AH250 | BW24: 1466 | BY24: Ware Ware | BZ24: 대광 | CA24: =A24&"&"&G24 -> 2&2025123704 | CB24: =IFERROR(MID(J24,FIND("R",J24)+1,2),"") -> 18 | CC24: - | CE24: =IFERROR(VLOOKUP(CA24,시험요청!EV:EZ,5,FALSE),"") -> 0
A25: 3 | B25: 3 | C25: RE | D25: 이병재 | E25: 이준탁 | F25: DM | G25: 2025120470 | H25: JF5 | I25: 2022673 | J25: LT275/55R20 | K25: PC05 | L25: 8 | M25: L | N25: B | O25: - | P25: HK | Q25: 0 | R25: 14 | S25: 01/20 화 | T25: RE/DM H107 | U25: Expand | V25: P95 | W25: U73 | X25: S25 | Y25: - (N) | Z25: DR75043 | AA25: 신제작 | AB25: 292 | AC25: S24 | AD25: B89 | AE25: DN67648 | AF25: B1005 | AG25: 190 | AH25: 850 | AI25: 2325 | AJ25: FY25532 | AK25: 540 | AL25: 505 | AM25: FR03639 | AN25: ET11006 | AO25: 710 | AP25: 90 | AQ25: FW02356 | AR25: ET11006 | AS25: 560 | AT25: 90 | AU25: FH25277 | AV25: ES12003 | AW25: 240 | AX25: 24 | AY25: FH25278 | AZ25: ES12003 | BA25: 225 | BB25: 24 | BC25: ET10121 | BD25: - | BE25: - | BF25: - | BG25: - | BH25: DN56899 | BI25: CQB86 | BJ25: TREAD | BK25: 40 | BL25: - | BN25: 20 | BO25: [정규용] 25DG4 25DG5 | BP25: BG0450 | BQ25: CE50Z25 | BR25: 51M | BT25: GU29497 | BU25: GW22395 | BV25: BU118 | BW25: 1634 | BX25: H107 C/C Turn-Up 68% | BY25: Making Making | BZ25: SYT | CA25: =A25&"&"&G25 -> 3&2025120470 | CB25: =IFERROR(MID(J25,FIND("R",J25)+1,2),"") -> 20 | CC25: - | CE25: =IFERROR(VLOOKUP(CA25,시험요청!EV:EZ,5,FALSE),"") -> 0
A26: 3 | B26: 3 | C26: 양산기술 | D26: 박찬휘 | E26: 김노연 | F26: DP | G26: 2026012134 | H26: JF505 | I26: 2022657 | J26: 195/75R16C | K26: RA58 | L26: 10 | M26: L | N26: B | O26: - | P26: HK | Q26: 3 | R26: 10 | S26: 01/20 화 | T26: RE/DP H192 | U26: Transfer Dev. | V26: T95 | W26: U36 | X26: S25 | Y26: U35 (F) | Z26: DR74910 | AA26: B1003 | AB26: 200 | AC26: S24 | AD26: B89 | AE26: DN69281 | AF26: 신제작 | AG26: 160 | AH26: 0 | AI26: 2010 | AJ26: FY25695 | AK26: 420 | AL26: 400 | AM26: FW02579 | AN26: ET10216 | AO26: 570 | AP26: 90 | AQ26: FR03431 | AR26: ET10216 | AS26: 410 | AT26: 90 | AU26: FHB0135 | AV26: ES20427 | AW26: 165 | AX26: 27 | AY26: FH25070 | AZ26: ES20427 | BA26: 150 | BB26: 27 | BC26: ET10121 | BD26: - | BE26: - | BF26: - | BG26: - | BH26: DN56899 | BI26: CQB86 | BJ26: TREAD | BK26: 40 | BL26: - | BN26: 16 | BO26: [정규용] 24Q04 24Q05 | BP26: BD41AI | BQ26: CA02N15 | BR26: 47M | BT26: GU28682 | BU26: GW66005 | BV26: BB315 | BW26: 1285 | BX26: 10PR / BIC 1285 | BY26: Ware Ware | BZ26: 대광 | CA26: =A26&"&"&G26 -> 3&2026012134 | CB26: =IFERROR(MID(J26,FIND("R",J26)+1,2),"") -> 16 | CC26: #2 C/C 변경 : Spec 변경 | CE26: =IFERROR(VLOOKUP(CA26,시험요청!EV:EZ,5,FALSE),"") -> 0
A27: 3 | B27: 3 | C27: 양산기술 | D27: 임서윤 | E27: 김영광 | F27: DP | G27: 2025102771 | H27: JF5 | I27: 2022660 | J27: 225/75R16C | K27: RA58 | L27: 10 | M27: L | N27: B | O27: - | P27: HK | Q27: 0 | R27: 10 | S27: 01/22 목 | T27: RE/DP H192 | U27: Transfer Dev. | V27: T95 | W27: U36 | X27: S25 | Y27: U35 (F) | Z27: DR74946 | AA27: 신제작 | AB27: 226 | AC27: S24 | AD27: B89 | AE27: DN69296 | AF27: 신제작 | AG27: 180 | AH27: 0 | AI27: 2145 | AJ27: FY25691 | AK27: 490 | AL27: 470 | AM27: FW01691 | AN27: ET10216 | AO27: 660 | AP27: 90 | AQ27: FR03423 | AR27: ET10216 | AS27: 470 | AT27: 90 | AU27: FHB0183 | AV27: ES20427 | AW27: 190 | AX27: 27 | AY27: FH25132 | AZ27: ES20427 | BA27: 175 | BB27: 27 | BC27: ET10121 | BD27: - | BE27: - | BF27: - | BG27: - | BH27: DN56899 | BI27: CQB86 | BJ27: TREAD | BK27: 40 | BL27: - | BN27: 16 | BO27: [정규용] 24Q28 24Q29 | BP27: B50750 | BQ27: CE09X15 | BR27: 47M | BT27: GU28682 | BU27: GW66005 | BV27: BB315 | BW27: 1285 | BX27: 10PR / BIC 1285 | BY27: Ware Ware | BZ27: 혜원 | CA27: =A27&"&"&G27 -> 3&2025102771 | CB27: =IFERROR(MID(J27,FIND("R",J27)+1,2),"") -> 16 | CC27: - | CE27: =IFERROR(VLOOKUP(CA27,시험요청!EV:EZ,5,FALSE),"") -> 0
A28: 3 | B28: 3 | C28: 양산기술 | D28: 장아영 | E28: 이준탁 | F28: DS | G28: 2025112434 | H28: JF0 | I28: 1035223 | J28: 225/50ZR18Y XL | K28: K137A | L28: 4 | M28: L | N28: B | O28: - | P28: HK | Q28: 2 | R28: 12 | S28: 01/22 목 | T28: RE/DS H172 | U28: Transfer Dev. | V28: P35 | W28: U35 | X28: S25 | Y28: - (C) | Z28: DR75009 | AA28: 신제작 | AB28: 242 | AC28: S24 | AD28: B89 | AE28: DN69053 | AF28: B1007 | AG28: 125 | AH28: 618 | AI28: 1985 | AJ28: FY24820 | AK28: 420 | AL28: 385 | AM28: FX26760 | AN28: ET10203 | AO28: 650 | AP28: 90 | AQ28: - | AR28: - | AS28: - | AT28: - | AU28: FH23629 | AV28: ES10262 | AW28: 205 | AX28: 30 | AY28: FX28671 | AZ28: ES10262 | BA28: 195 | BB28: 30 | BC28: ET10151 | BD28: - | BE28: - | BF28: - | BG28: - | BH28: - | BI28: - | BJ28: STOS | BK28: - | BL28: - | BN28: 18 | BO28: [정규용] 23K96 23K97 (KP) | BP28: BE46AI | BQ28: CE09K11 | BR28: 47M | BT28: GU28444 | BU28: GW21956 | BV28: DT220 | BW28: 1462 | BX28: KP 정규 생산(~2주차) 후, 몰드 임대 예정 Aramid JLB | BZ28: HPW | CA28: =A28&"&"&G28 -> 3&2025112434 | CB28: =IFERROR(MID(J28,FIND("R",J28)+1,2),"") -> 18 | CC28: - | CE28: =IFERROR(VLOOKUP(CA28,시험요청!EV:EZ,5,FALSE),"") -> 0
A29: 3 | B29: 3 | C29: 양산기술 | D29: 최형인 | E29: 이준탁 | F29: DS | G29: 2025121882 | H29: JF5 | I29: 1027947 | J29: 245/45R18W XL | K29: K135 | L29: 4 | M29: L | N29: B | O29: Q | P29: HK | Q29: 0 | R29: 12 | S29: 01/23 금 | T29: RE/DS H172 | U29: Transfer Dev. | V29: P37 | W29: U36 | X29: S25 | Y29: U35 (C) | Z29: DR75076 | AA29: 신제작 | AB29: 254 | AC29: S24 | AD29: B89 | AE29: DN69449 | AF29: 신제작 | AG29: 125 | AH29: 604 | AI29: 1970 | AJ29: FY24753 | AK29: 410 | AL29: 375 | AM29: FX26757 | AN29: ET10203 | AO29: 630 | AP29: 90 | AQ29: - | AR29: - | AS29: - | AT29: - | AU29: FHB0005 | AV29: ES10262 | AW29: 210 | AX29: 27 | AY29: FX27880 | AZ29: ES10262 | BA29: 200 | BB29: 27 | BC29: ET10121 | BD29: - | BE29: - | BF29: - | BG29: - | BH29: - | BI29: - | BJ29: STOS | BK29: - | BL29: - | BN29: 18 | BO29: [정규용] 24892 24893 (개조중, KP | BP29: BE0145 | BQ29: CE09X12 | BR29: 47M | BT29: GU28436 | BU29: GW21956 | BV29: AT225 | BW29: 1462 | BZ29: 혜원 | CA29: =A29&"&"&G29 -> 3&2025121882 | CB29: =IFERROR(MID(J29,FIND("R",J29)+1,2),"") -> 18 | CC29: - | CE29: =IFERROR(VLOOKUP(CA29,시험요청!EV:EZ,5,FALSE),"") -> 0
